Workbook
Name a_1: 'Нормальний переріз'!$D$26
Name a_2: 'Нормальний переріз'!$D$27
Name a_3: 'Нормальний переріз'!$D$28
Name a_4: 'Нормальний переріз'!$D$29
Name a_5: 'Нормальний переріз'!$D$30
Name A_c: 'Похилий переріз'!$D$35*'Похилий переріз'!$F$35
Name A_s1: 'Вихідні дані'!$D$14*'Вихідні дані'!$F$14
Name A_s2: 'Вихідні дані'!$D$15*'Вихідні дані'!$F$15
Name A_sl: 'Похилий переріз'!$D$16*'Похилий переріз'!$F$16
Name A_sw: 'Похилий переріз'!$D$61*'Похилий переріз'!$F$61
Name a_v: 'Похилий переріз'!$D$7*'Похилий переріз'!$F$7
Name AR_Arm_Names: 'Табл. 3.4_ДСТУ'!$C$3:$H$3
Name AR_Con_Name: 'Табл. 3.1_Д1_ДБН'!$C$2:$M$2
Name AR_VarTypes: Вимірність!$A$2:$A$29
Name Arm_Dim_Names: 'Сорт. Арм.'!$A$2:$A$18
Name Arm_Name: 'Вихідні дані'!$D$8
Name b: 'Вихідні дані'!$D$2*'Вихідні дані'!$F$2
Name b_w: 'Похилий переріз'!$D$19*'Похилий переріз'!$F$19
Name C_Rdc: 'Похилий переріз'!$D$40
Name Con_Name: 'Вихідні дані'!$D$6
Name cotθ_2.5: 'Похилий переріз'!$D$73
Name d: 'Похилий переріз'!$D$20*'Похилий переріз'!$F$20
Name e: 'Нормальний переріз'!$D$17*'Нормальний переріз'!$F$17
Name E_s: 'Нормальний переріз'!$D$33
Name f_cd: 'Нормальний переріз'!$D$21
Name f_ck: 'Похилий переріз'!$D$13*'Похилий переріз'!$F$13
Name F_s1: 'Нормальний переріз'!$D$57
Name F_s2: 'Нормальний переріз'!$D$58
Name f_yk: 'Нормальний переріз'!$D$32
Name h: 'Вихідні дані'!$D$3*'Вихідні дані'!$F$3
Name k: IF('Похилий переріз'!$D$29<='Похилий переріз'!$H$29,'Похилий переріз'!$D$29,'Похилий переріз'!$H$29)
Name k_1: 'Похилий переріз'!$D$41
Name L_1: 'Похилий переріз'!$D$5*'Похилий переріз'!$F$5
Name M: 'Вихідні дані'!$D$19*'Вихідні дані'!$F$19
Name N: 'Вихідні дані'!$D$21*'Вихідні дані'!$F$21
Name N_ed: 'Похилий переріз'!$D$23*'Похилий переріз'!$F$23
Name Q: 'Вихідні дані'!$D$20*'Вихідні дані'!$F$20
Name RES_FindPointNum: 'Розвязок системи рівнянь'!$AS:$AS
Name s: 'Похилий переріз'!$D$62*'Похилий переріз'!$F$62
Name Tabl_2.1_DBN: 'Табл. 3.4_ДСТУ'!$C$12:$H$12
Name Tabl_2.1_DBN_Names: 'Табл. 3.4_ДСТУ'!$A$12
Name Tabl_3.1_DBN: 'Табл. 3.1_Д1_ДБН'!$C$3:$M$20
Name Tabl_3.1_DBN_Names: 'Табл. 3.1_Д1_ДБН'!$A$3:$A$20
Name Tabl_3.4_DSTY: 'Табл. 3.4_ДСТУ'!$C$5:$H$8
Name Tabl_3.4_DSTY_Names: 'Табл. 3.4_ДСТУ'!$A$5:$A$8
Name Tabl_Arm_Area: 'Сорт. Арм.'!$B$2:$B$18
Name Tabl_D1_DBN: 'Табл. 3.1_Д1_ДБН'!$C$26:$M$30
Name Tabl_D1_DBN_Names: 'Табл. 3.1_Д1_ДБН'!$A$26:$A$30
Name V_ed: 'Похилий переріз'!$D$27*'Похилий переріз'!$F$27
Name V_min: 'Похилий переріз'!$D$42
Name V_Rdc: 'Похилий переріз'!$D$45*'Похилий переріз'!$F$45
Name V_Rdmax_2.5: 'Похилий переріз'!$D$75
Name VarNames: Налаштування!$F:$F
Name VarType: Налаштування!$G:$G
Name X_1: 'Нормальний переріз'!$D$47
Name y: 'Вихідні дані'!$D$4*'Вихідні дані'!$F$4
Name z: 'Похилий переріз'!$D$69*'Похилий переріз'!$F$69
Name Z_s1: 'Вихідні дані'!$D$16*'Вихідні дані'!$F$16
Name Z_s2: 'Вихідні дані'!$D$17*'Вихідні дані'!$F$17
Name α: 'Похилий переріз'!$D$60

Sheet Вихідні дані
A2: Ширина перерізу | C2: b= | D2: 0.5 | E2: м | F2: =INDEX(Вимірність!B:C,MATCH(E2,Вимірність!B:B,0),2)
A3: Висота перерізу | C3: h= | D3: 0.5 | E3: м | F3: =INDEX(Вимірність!B:C,MATCH(E3,Вимірність!B:B,0),2)
A4: Центр ваги перерізу | C4: y= | D4: =0.5*h | E4: м | F4: =INDEX(Вимірність!B:C,MATCH(E4,Вимірність!B:B,0),2)
A6: Клас бетону | D6: C25/30
A7: Коеф. Надійності | C7: γ_с= | D7: 1.3
A8: Клас арматури | D8: А400С
B13: Армування
A14: 7 | B14: 28 | C14: A_s1= | D14: =INDEX(Tabl_Arm_Area,MATCH(B14,Arm_Dim_Names,0),1)*A14/100/100/F14 | E14: мм2 | F14: =INDEX(Вимірність!B:C,MATCH(E14,Вимірність!B:B,0),2)
A15: 7 | B15: 28 | C15: A_s2= | D15: =INDEX(Tabl_Arm_Area,MATCH(B15,Arm_Dim_Names,0),1)*A15/100/100/F15 | E15: м2 | F15: =INDEX(Вимірність!B:C,MATCH(E15,Вимірність!B:B,0),2)
C16: Z_s1= | D16: 0.03 | E16: м | F16: =INDEX(Вимірність!B:C,MATCH(E16,Вимірність!B:B,0),2)
C17: Z_s2= | D17: =0.5-0.03 | E17: м | F17: =INDEX(Вимірність!B:C,MATCH(E17,Вимірність!B:B,0),2)
B18: Зусилля в перерізі
C19: M= | D19: 0 | E19: т*м | F19: =INDEX(Вимірність!B:C,MATCH(E19,Вимірність!B:B,0),2)
C20: Q= | D20: 0 | E20: kH | F20: =INDEX(Вимірність!B:C,MATCH(E20,Вимірність!B:B,0),2)
C21: N= | D21: 0 | E21: kH | F21: =INDEX(Вимірність!B:C,MATCH(E21,Вимірність!B:B,0),2)

Sheet Нормальний переріз
A2: Ширина перерізу | C2: b= | D2: =b
A3: Висота перерізу | C3: h= | D3: =h
A4: Центр ваги перерізу | C4: y= | D4: =y
A6: Клас бетону
A7: Клас арматури
B8: Армування
C9: A_s1= | D9: =A_s1
C10: A_s2= | D10: =A_s2
C11: Z_s1= | D11: =Z_s1
C12: Z_s2= | D12: =Z_s2
B13: Зусилля в перерізі
C14: M= | D14: =M
C15: Q= | D15: =Q
C16: N= | D16: =N | P16: =D72
C17: e= | D17: 0.15 | E17: м | F17: =INDEX(Вимірність!B:C,MATCH(E17,Вимірність!B:B,0),2) | P17: =G72
B19: Збір даних:
B20: Бетон
C21: f_cd= | D21: =INDEX(Tabl_3.1_DBN,MATCH(LEFT(C21,LEN(C21)-1),Tabl_3.1_DBN_Names,0),MATCH(Con_Name,AR_Con_Name,0)) | E21: МПа | F21: =INDEX(Вимірність!B:C,MATCH(E21,Вимірність!B:B,0),2) | G21: розрахункове значення міцності бетону на стиск
C22: ε_(cu1, cd)= | D22: =INDEX(Tabl_3.1_DBN,MATCH(LEFT(C22,LEN(C22)-1),Tabl_3.1_DBN_Names,0),MATCH(Con_Name,AR_Con_Name,0)) | E22: ‰ | F22: =INDEX(Вимірність!B:C,MATCH(E22,Вимірність!B:B,0),2) | G22: гранична деформація стиску бетону;
C23: ε_(c1, cd)= | D23: =INDEX(Tabl_3.1_DBN,MATCH(LEFT(C23,LEN(C23)-1),Tabl_3.1_DBN_Names,0),MATCH(Con_Name,AR_Con_Name,0)) | E23: ‰ | F23: =INDEX(Вимірність!B:C,MATCH(E23,Вимірність!B:B,0),2) | G23: деформація при максимальних напруженнях;
B25: За додатком Д[1] визначаємо коефіцієнти полінома ak
C26: a_1= | D26: =INDEX(Tabl_D1_DBN,MATCH(LEFT(C26,LEN(C26)-1),Tabl_D1_DBN_Names,0),MATCH(Con_Name,AR_Con_Name,0))
C27: a_2= | D27: =INDEX(Tabl_D1_DBN,MATCH(LEFT(C27,LEN(C27)-1),Tabl_D1_DBN_Names,0),MATCH(Con_Name,AR_Con_Name,0))
C28: a_3= | D28: =INDEX(Tabl_D1_DBN,MATCH(LEFT(C28,LEN(C28)-1),Tabl_D1_DBN_Names,0),MATCH(Con_Name,AR_Con_Name,0))
C29: a_4= | D29: =INDEX(Tabl_D1_DBN,MATCH(LEFT(C29,LEN(C29)-1),Tabl_D1_DBN_Names,0),MATCH(Con_Name,AR_Con_Name,0))
C30: a_5= | D30: =INDEX(Tabl_D1_DBN,MATCH(LEFT(C30,LEN(C30)-1),Tabl_D1_DBN_Names,0),MATCH(Con_Name,AR_Con_Name,0))
C32: f_yk= | D32: =INDEX(Tabl_3.4_DSTY,MATCH(LEFT(C32,LEN(C32)-1),Tabl_3.4_DSTY_Names,0),MATCH(Arm_Name,AR_Arm_Names,0)) | E32: МПа | F32: =INDEX(Вимірність!B:C,MATCH(E32,Вимірність!B:B,0),2) | G32: характеристичне значення міцності арматури на границі текучості;
C33: E_s= | D33: =INDEX(Tabl_3.4_DSTY,MATCH(LEFT(C33,LEN(C33)-1),Tabl_3.4_DSTY_Names,0),MATCH(Arm_Name,AR_Arm_Names,0)) | E33: МПа | F33: =INDEX(Вимірність!B:C,MATCH(E33,Вимірність!B:B,0),2) | G33: фактичний модуль пружності арматури;
C35: γ_s = | D35: =INDEX(Tabl_2.1_DBN,1,MATCH(Arm_Name,AR_Arm_Names,0)) | G35: коефіцієнт надійності арматури
C37: f_yd= | D37: =f_yk/γ_s | E37: =E32 | F37: =INDEX(Вимірність!B:C,MATCH(E37,Вимірність!B:B,0),2) | G37: розрахункове значення міцності арматури на границі текучості.
B39: Розрахунок:
B40: Крок 0
C41: ε_c1= | D41: =F41*F22 | F41: 0.328
C42: ε_c2= | D42: =F42*F23 | F42: -0.0694 | G42: Деформація бетону на менш стиснутій грані
C44: χ= | D44: =(ε_c1-ε_c2)/h | E44: 1/м | F44: =INDEX(Вимірність!B:C,MATCH(E44,Вимірність!B:B,0),2) | G44: кривизна
C45: γ= | D45: =ε_c1/(ε_c1cd) | G45: відношення деформацій
C47: X_1= | D47: =ε_c1/χ | E47: м | F47: =INDEX(Вимірність!B:C,MATCH(E47,Вимірність!B:B,0),2) | G47: висота стиснутої зони бетону
C49: χ ̅= | D49: =χ/(ε_c1cd) | G49: відносна кривизна
C51: ε_s1= | D51: =χ*(X_1-Z_s1) | G51: деформація арматруи
C52: ε_s2= | D52: =χ*(X_1-Z_s2)
...

Sheet Похилий переріз
A1: Елементи що не потребують розрахункового поперечного армувння
B2: Додаткові вихідні дані:
A3: Місце прикладання сили: | D3: Зверху
A4: Тип навантаження: | D4: Зосереджене
C5: L_1= | D5: 0 | E5: м | F5: =INDEX(Вимірність!B:C,MATCH(E5,Вимірність!B:B,0),2) | G5: Відстань від грані опори до розрахункового перерізу
C6: a_v= | D6: 0.3 | E6: м | F6: =INDEX(Вимірність!B:C,MATCH(E6,Вимірність!B:B,0),2) | G6: =IF(D6<=H6,"<=",">") | H6: =0.5*d/J6 | I6: =E6 | J6: =INDEX(Вимірність!B:C,MATCH(I6,Вимірність!B:B,0),2) | K6: Відстань від грані опори до прикладання сили | P6: п. 4.6.2.6
C7: a_v= | D7: =IF(D6>H6,D6,H6) | E7: =E6 | F7: =INDEX(Вимірність!B:C,MATCH(E7,Вимірність!B:B,0),2)
A8: Умова 1. Місце розташування розрахункового перерізу (п. 4.6.1.4):
C9: =IF(AND(L_1<d,$D$4="Розподілене"),"Перевірки перерізу на цій відстані від опори не потрібно. Виберіть переріз на відстані що найменше "&h&" м і уточніть величину Q","Потрібен подальший розрахунок")
B11: Збір даних:
B12: Бетон
C13: f_ck= | D13: =INDEX(Tabl_3.1_DBN,MATCH(LEFT(C13,LEN(C13)-1),Tabl_3.1_DBN_Names,0),MATCH(Con_Name,AR_Con_Name,0))/F13 | E13: м | F13: =INDEX(Вимірність!B:C,MATCH(E13,Вимірність!B:B,0),2) | G13: Характеристичне значення міцності бетону на стиск
B15: Арматура
C16: A_sl= | D16: =A_s2/F16 | E16: м2 | F16: =INDEX(Вимірність!B:C,MATCH(E16,Вимірність!B:B,0),2) | G16: Площа розтянутої арматури ,яка заанкерена на відстань
A18: із | B18: Переріз
C19: b_w= | D19: =b/F19 | E19: м | F19: =INDEX(Вимірність!B:C,MATCH(E19,Вимірність!B:B,0),2) | G19: Найменша ширина поперечного перерізу в розтянутій зоні
C20: d= | D20: =Z_s2/F20 | E20: м | F20: =INDEX(Вимірність!B:C,MATCH(E20,Вимірність!B:B,0),2)
B22: Зусилля в перерізі
C23: N_ed= | D23: =N/F23 | E23: MH | F23: =INDEX(Вимірність!B:C,MATCH(E23,Вимірність!B:B,0),2)
B25: Розрахунок
C26: β= | D26: =IF(AND(a_v<=2*d, a_v>=0.5*d,$D$3="Зверху",$D$4="Зосереджене"), a_v/(2*h),1) | G26: п. 4.6.2.6
C27: V_ed= | D27: =Q/F27 | E27: MH | F27: =INDEX(Вимірність!B:C,MATCH(E27,Вимірність!B:B,0),2) | G27: Розрахункове значення поперечної сили в перерізі
C29: k= | D29: =1+(200/(d*1000))^(1/2) | G29: =IF(D29<=H29,"<=",">") | H29: =2
C30: k= | D30: =k | G30: Коефіцієнт висоти перерізу
C32: ρ_1= | D32: =A_sl/(b_w*d) | G32: =IF(D32<=H32,"<=",">") | H32: 0.02
C33: ρ_1= | D33: =ρ_1 | G33: Коефіцієнт розтянутого армування
C35: A_c= | D35: =b*h/F35 | E35: см2 | F35: =INDEX(Вимірність!B:C,MATCH(E35,Вимірність!B:B,0),2) | G35: Площа поперечного перерізу
A38: Формула (4.38) | C38: σ_cp= | D38: =N_ed/A_c/F38 | E38: МПа | F38: =INDEX(Вимірність!B:C,MATCH(E38,Вимірність!B:B,0),2) | G38: Напруження в бетоні від осьового навантаження
C40: C_Rdc= | D40: =0.18/γ_с
C41: k_1= | D41: 0.15
C42: V_min= | D42: =0.035*k^(3/2)*f_ck^(0.5)/F42 | E42: MH | F42: =INDEX(Вимірність!B:C,MATCH(E42,Вимірність!B:B,0),2) | G42: Формула (4.39)
A43: Формули (4.36) та (4.37)
C44: V_Rdc= | D44: =(C_Rdc*k*(100*ρ_1*f_ck)^(1/3)+k_1*σ_cp)*b_w*d/F44 | E44: MH | F44: =INDEX(Вимірність!B:C,MATCH(E44,Вимірність!B:B,0),2) | G44: =IF(D44<=H44,"<=",">") | H44: =(V_min+k_1*σ_cp)*b_w*d/J44 | I44: =E44 | J44: =INDEX(Вимірність!B:C,MATCH(I44,Вимірність!B:B,0),2)
C45: V_Rdc= | D45: =IF(D44<=H44,H44,D44) | E45: =E44 | F45: =INDEX(Вимірність!B:C,MATCH(E45,Вимірність!B:B,0),2) | G45: Розрахункова величина опору переізу без армування на зсув
A47: Умова 2 міцності перерізу з паралельними поясами без армування на зсув (п. 4.6.1.2):
C48: =C45 | D48: =V_Rdc/F48 | E48: MH | F48: =INDEX(Вимірність!B:C,MATCH(E48,Вимірність!B:B,0),2) | G48: =IF(D48<=I48,"<=",">") | H48: V_ed*β= | I48: =V_ed*β/K48 | J48: =E48 | K48: =INDEX(Вимірність!B:C,MATCH(J48,Вимірність!B:B,0),2) | L48: =IF(G48=">","Умова виконується. Коефіцієнт використання К= "&ROUND(I48/D48*100,3)&" %","Умова не виконується. Коефіцієнт використання К= "&ROUND(I48/D48*100,3)&" %""")
C50: ν= | D50: =0.6*(1-f_ck/250) | G50: Коефіцієнт зниження міцності бетону з тріщинами при зсуві
A52: Умова 3 міцності перерізу з паралельними поясами без армування на зсув (п. 4.6.1.7):
C53: V_Rd= | D53: =0.5*b_w*d*ν*f_cd/F53 | E53: MH | F53: =INDEX(Вимірність!B:C,MATCH(E53,Вимірність!B:B,0),2) | G53: =IF(D53<=I53,"<=",">") | H53: V_ed= | I53: =V_ed/K53 | J53: =E53 | K53: =INDEX(Вимірність!B:C,MATCH(J53,Вимірність!B:B,0),2) | L53: =IF(G53=">","Умова виконується. Коефіцієнт використання К= "&ROUND(I53/D53*100,3)&" %","Умова не виконується. Коефіцієнт використання К= "&ROUND(I53/D53*100,3)&" %""")
A55: Додаткові вимоги:
...

Sheet Табл. 3.4_ДСТУ
A1: Таблиця 3.4 – Міцністні та деформаційні характеристики арматури
A2: Характеристика арматури | C2: Клас арматури
C3: А240С | D3: Вр-I | E3: А400С | F3: А500С | G3: А500С | H3: В500
F4: Ø8-22 | G4: Ø25-40
A5: f_yk | B5: (МПа) | C5: 240 | D5: 405 | E5: 400 | F5: 500 | G5: 500 | H5: 500
A6: f_ywd | B6: (МПа) | C6: 170 | D6: 283 | E6: 285 | F6: 300 | G6: 300 | H6: 300
A7: E_s | B7: (МПа) | C7: =2.1*10^5 | D7: =2.1*10^5 | E7: =2.1*10^5 | F7: =2*10^5 | G7: =2*10^5 | H7: =1.9*10^5
A8: ε_ud | C8: 0.025 | D8: 0.025 | E8: 0.025 | F8: 0.02 | G8: 0.02 | H8: 0.012
A10: Таблиця 2,1 – Коефіцієнти надійності матеріалів для граничних станів
C11: А240С | D11: Вр-I | E11: А400С | F11: А500С | G11: А500С | H11: В500
A12: γ_s | C12: 1.05 | D12: 1.25 | E12: 1.1 | F12: 1.15 | G12: 1.2 | H12: =D12

Sheet Табл. 3.1_Д1_ДБН
A1: Клас міцності бетону | N1: Аналітична залежність / пояснення
C2: C8/10 | D2: C12/15 | E2: C16/20 | F2: C20/25 | G2: C25/30 | H2: C30/35 | I2: C32/40 | J2: C35/45 | K2: C40/50 | L2: C45/55 | M2: C50/60
A3: fck, cube | B3: (МПа) | C3: 10 | D3: 15 | E3: 20 | F3: 25 | G3: 30 | H3: 35 | I3: 40 | J3: 45 | K3: 50 | L3: 55 | M3: 60
A4: fcm, cube | B4: (МПа) | C4: 13 | D4: 19 | E4: 25 | F4: 32 | G4: 38 | H4: 45 | I4: 51 | J4: 58 | K4: 64 | L4: 71 | M4: 77 | N4: fcm, cube = fck, cube / (1 – 1,64Vc)*)
A5: f_ck | B5: (МПа) | C5: 7.5 | D5: 11 | E5: 15 | F5: 18.5 | G5: 22 | H5: 25.5 | I5: 29 | J5: 32 | K5: 36 | L5: 39.5 | M5: 43
A6: f_cd | B6: (МПа) | C6: 6 | D6: 8.5 | E6: 11.5 | F6: 14.5 | G6: 17 | H6: 19.5 | I6: 22 | J6: 25 | K6: 27.5 | L6: 30 | M6: 33 | N6: fcd = fck / γc
A7: fctm | B7: (МПа) | C7: 1.2 | D7: 1.6 | E7: 1.9 | F7: 2.2 | G7: 2.6 | H7: 2.8 | I7: 3 | J7: 3.2 | K7: 3.5 | L7: 3.8 | M7: 4.1
A8: fctk, 0,05 | B8: (МПа) | C8: 0.8 | D8: 1.1 | E8: 1.3 | F8: 1.5 | G8: 1.8 | H8: 2 | I8: 2.1 | J8: 2.2 | K8: 2.5 | L8: 2.7 | M8: 3 | N8: fctk, 0,05 = 0,7 fctm 5 % вибірки
A9: fctk, 0,95 | B9: (МПа) | C9: 1.6 | D9: 2 | E9: 2.5 | F9: 2.9 | G9: 3.4 | H9: 3.6 | I9: 3.9 | J9: 4.2 | K9: 4.6 | L9: 4.9 | M9: 5.3 | N9: fctk, 0,95 = 1,3 fctm 95 % вибірки
A10: Есm (ГПа) | C10: 18 | D10: 23 | E10: 27 | F10: 30 | G10: 32.5 | H10: 34.5 | I10: 36 | J10: 37.5 | K10: 39 | L10: 39.5 | M10: 40
A11: Еck (ГПа) | C11: 15 | D11: 20 | E11: 23 | F11: 26 | G11: 29 | H11: 31 | I11: 32 | J11: 34 | K11: 35 | L11: 36 | M11: 37
A12: Еcd (ГПа) | C12: 12.6 | D12: 16.3 | E12: 20 | F12: 23 | G12: 25 | H12: 27 | I12: 28.5 | J12: 30.5 | K12: 32 | L12: 33 | M12: 34
A13: εc1, сk (0/00) | C13: 1.57 | D13: 1.61 | E13: 1.66 | F13: 1.71 | G13: 1.76 | H13: 1.81 | I13: 1.86 | J13: 1.9 | K13: 1.94 | L13: 1.98 | M13: 2.02
A14: ε_(c1, cd) | B14: (0/00) | C14: 1.56 | D14: 1.58 | E14: 1.62 | F14: 1.65 | G14: 1.69 | H14: 1.72 | I14: 1.76 | J14: 1.8 | K14: 1.84 | L14: 1.87 | M14: 1.91
A15: εcu1, сk (0/00) | C15: 4.5 | D15: 4.4 | E15: 4.15 | F15: 3.85 | G15: 3.55 | H15: 3.25 | I15: 3 | J15: 2.83 | K15: 2.63 | L15: 2.5 | M15: 2.4
A16: ε_(cu1, cd) | B16: (0/00) | C16: 3.75 | D16: 3.7 | E16: 3.59 | F16: 3.44 | G16: 3.28 | H16: 3.1 | I16: 2.93 | J16: 2.72 | K16: 2.57 | L16: 2.43 | M16: 2.29
A17: εc3, сk (0/00) | C17: 0.5 | D17: 0.55 | E17: 0.65 | F17: 0.71 | G17: 0.76 | H17: 0.82 | I17: 0.91 | J17: 0.94 | K17: 1.03 | L17: 1.1 | M17: 1.16 | N17: с3, ck = fck, prism / Eck
A18: εc3, сd (0/00) | C18: 0.48 | D18: 0.52 | E18: 0.58 | F18: 0.63 | G18: 0.68 | H18: 0.72 | I18: 0.77 | J18: 0.83 | K18: 0.86 | L18: 0.91 | M18: 0.97 | N18: с3, cd = fcd / Ecd
A19: εcu3, сk (0/00) | C19: 4.05 | D19: 3.96 | E19: 3.73 | F19: 3.46 | G19: 3.2 | H19: 2.93 | I19: 2.7 | J19: 2.55 | K19: 2.37 | L19: 2.25 | M19: 2.16 | N19: εcu3, ck = 0,9 εcu1, ck
A20: εcu3, сd (0/00) | C20: 3.38 | D20: 3.33 | E20: 3.23 | F20: 3.1 | G20: 3 | H20: 2.8 | I20: 2.64 | J20: 2.45 | K20: 2.31 | L20: 2.19 | M20: 2.06 | N20: εcu3, cd = 0,9 εcu1, cd
A21: *) – величини fcm cube в таблиці наведені виходячи зі значення коефіцієнта варіації Vc, який дорівнює 13,5 %.
A23: Таблиця Д.1 – Коефіцієнти ak для розрахунків за першою групою граничних станів
A24: Коефі-цієнт | C24: Клас бетону на стиск
C25: С 8/10 | D25: С 12/15 | E25: С 16/20 | F25: С 20/25 | G25: С 25/30 | H25: С 30/35 | I25: С 32/40 | J25: С 35/45 | K25: С 40/50 | L25: С 45/55 | M25: С 50/60
A26: a_1 | C26: 3.6082 | D26: 3.3358 | E26: 3.0798 | F26: 2.8785 | G26: 2.7404 | H26: 2.6219 | I26: 2.51816 | J26: 2.40816 | K26: 2.32566 | L26: 2.24964 | M26: 2.1653
A27: a_2 | C27: -5.1559 | D27: -4.4171 | E27: -3.7184 | F27: -3.1586 | G27: -2.7649 | H27: -2.425 | I27: -2.14804 | J27: -1.9689 | K27: -2.1144 | L27: -2.2642 | M27: -2.2379
A28: a_3 | C28: 3.6537 | D28: 2.9586 | E28: 2.2946 | F28: 1.7454 | G28: 1.3416 | H28: 0.98327 | I28: 0.71003 | J28: 0.6885 | K28: 1.3717 | L28: 2.04693 | M28: 2.2202
A29: a_4 | C29: -1.2723 | D29: -1.0093 | E29: -0.7533 | F29: -0.52904 | G29: -0.35004 | H29: -0.17908 | I29: =-4.839 *10^(-2) | J29: -0.10286 | K29: -0.70272 | L29: -1.3 | M29: -1.3876
A30: a_5 | C30: 0.1663 | D30: 0.1319 | E30: =9.727*10^(-2) | F30: =6.374*10^(-2) | G30: =3.295*10^(-2) | H30: =-1.067*10^(-3) | I30: =-3.169*10^(-2) | J30: =-2.488*10^(-2) | K30: 0.11981 | L30: 0.2675 | M30: 0.4008

Sheet Сорт. Арм.
A1: Діаметр | B1: Розрахункова площа см2
A2: 3 | B2: 0.071
A3: 4 | B3: 0.126
A4: 5 | B4: 0.196
A5: 6 | B5: 0.283
A6: 8 | B6: 0.503
A7: 10 | B7: 0.789
A8: 12 | B8: 1.131
A9: 14 | B9: 1.539
A10: 16 | B10: 2.011
A11: 18 | B11: 2.545
A12: 20 | B12: 3.142
A13: 22 | B13: 3.801
... A18: 40 | B18: 12.56

Sheet Розвязок системи рівнянь
A1: Крок | B1: Підбір значення | E1: Новий крок | U1: Поліном для (4.1) | Z1: Поліном для (4.2) | AF1: 1-ша форма рівноваги | AJ1: 2-а форма рівноваги | AO1: Зніна знаку без розвязку | AP1: Точка Знайдена | AQ1: Точність
A2: k= | B2: Δε_c1= | C2: ='Нормальний переріз'!C41 | D2: Форма рівноваги | E2: Δε_c2= | F2: 1 | G2: 2 | H2: ε_c2= | I2: χ= | J2: γ= | K2: X_1= | L2: χ ̅= | M2: ε_s1= | N2: ε_s2= | O2: σ_s1= | P2: σ_s2= | Q2: F_s1= | R2: F_s2= | S2: Fsi(X1-Zsi) | T2: Fsi(X1-Zsi) | U2: 1 | V2: 2 | W2: 3 | X2: 4 | Y2: 5 | Z2: 1 | AA2: 2 | AB2: 3 | AC2: 4 | AD2: 5 | AE2: (4,1) N= | AF2: M1= [МHм] | AG2: (4,2) | AH2: Функція змінила знак | AI2: Точка Знайдена | AJ2: N= [MH] (4.3) | AK2: M2= [МHм] | AL2: (4,4) | AM2: Функція змінила знак | AN2: Точка Знайдена | AQ2: =0.02*ε_cu1cd
A3: 1 | B3: =IF(A3=1,0,IF(AP3,0.1*ε_cu1cd,0)) | C3: =IF(A3=1,0.1*ε_cu1cd,C2+B2) | D3: =IF('Нормальний переріз'!$D$68>0,1,2) | E3: =IF(D3=1,F3,G3) | F3: =0.11*ε_cu1cd | G3: =-0.1*ε_cu1cd | H3: =IF(A3=1,0,IF(AO2,H2-E2+E3,H2+E3)) | I3: =(C3-H3)/h | J3: =C3/(ε_c1cd) | K3: =C3/I3 | L3: =I3/(ε_c1cd) | M3: =I3*(K3-Z_s1) | N3: =I3*(K3-Z_s2) | O3: =E_s*M3 | P3: =E_s*N3 | Q3: =O3*A_s1 | R3: =P3*A_s2 | S3: =Q3*($K3-Z_s1) | T3: =R3*($K3-Z_s2) | U3: =(INDIRECT("a_"&U$2)/(U$2+1))*(($C3^(U$2+1)-$H3^(U$2+1))/(ε_c1cd^(U$2+1))) | V3: =(INDIRECT("a_"&V$2)/(V$2+1))*(($C3^(V$2+1)-$H3^(V$2+1))/(ε_c1cd^(V$2+1))) | W3: =(INDIRECT("a_"&W$2)/(W$2+1))*(($C3^(W$2+1)-$H3^(W$2+1))/(ε_c1cd^(W$2+1))) | X3: =(INDIRECT("a_"&X$2)/(X$2+1))*(($C3^(X$2+1)-$H3^(X$2+1))/(ε_c1cd^(X$2+1))) | Y3: =(INDIRECT("a_"&Y$2)/(Y$2+1))*(($C3^(Y$2+1)-$H3^(Y$2+1))/(ε_c1cd^(Y$2+1))) | Z3: =(INDIRECT("a_"&Z$2)/(Z$2+2))*(($C3^(Z$2+2)-$H3^(Z$2+2))/(ε_c1cd^(Z$2+2))) | AA3: =(INDIRECT("a_"&AA$2)/(AA$2+2))*(($C3^(AA$2+2)-$H3^(AA$2+2))/(ε_c1cd^(AA$2+2))) | AB3: =(INDIRECT("a_"&AB$2)/(AB$2+2))*(($C3^(AB$2+2)-$H3^(AB$2+2))/(ε_c1cd^(AB$2+2))) | AC3: =(INDIRECT("a_"&AC$2)/(AC$2+2))*(($C3^(AC$2+2)-$H3^(AC$2+2))/(ε_c1cd^(AC$2+2))) | AD3: =(INDIRECT("a_"&AD$2)/(AD$2+2))*(($C3^(AD$2+2)-$H3^(AD$2+2))/(ε_c1cd^(AD$2+2))) | AE3: =(b*f_cd/L3)*SUM(U3:Y3)+SUM(Q3:R3) | AF3: =AE3*(K3-y+e) | AG3: =(b*f_cd/(L3^2))*SUM(Z3:AD3)+SUM(S3:T3)-AF3 | AH3: =AG3<0 | AI3: =IF(A3=1,FALSE,(AND(AQ3,AH3,NOT(AI2)))) | AJ3: =(b*f_cd/L3)*(a_1/2*J3^2+a_2/3*J3^3+a_3/4*J3^4+a_4/5*J3^5+a_5/6*J3^6)+SUM(Q3:R3) | AK3: =AJ3*(K3-y+e) | AL3: =(b*f_cd/(L3^2))*(a_1/3*J3^3+a_2/4*J3^4+a_3/5*J3^5+a_4/6*J3^6+a_5/7*J3^7)+SUM(S3:T3)-AK3 | AM3: =AL3>0 | AN3: =IF(A3=1,FALSE,(AND(AQ3,AM3,NOT(AN2)))) | AO3: =IF(D3=1,AND(AH3,NOT(AI3)),AND(AM3,NOT(AN3))) | AP3: =IF(D3=1,AI3,AN3) | AQ3: =ABS(E3)<$AQ$2 | AS3: =IF(AP3,MAX(AS1:AS$3)+1,"")
A4: 2 | B4: =IF(A4=1,0,IF(AP4,0.1*ε_cu1cd,0)) | C4: =IF(A4=1,0.1*ε_cu1cd,C3+B3) | D4: =IF('Нормальний переріз'!$D$68>0,1,2) | E4: =IF(D4=1,F4,G4) | F4: =IF(AI3,0.11*ε_cu1cd,IF(AH3,F3*0.01,F3)) | G4: =IF(AP3,-0.1*ε_cu1cd,IF(AM3,G3*0.01,G3)) | H4: =IF(A4=1,E4,IF(AO3,H3-E3+E4,IF(AP3,0.8*H3,H3+E4))) | I4: =(C4-H4)/h | J4: =C4/(ε_c1cd) | K4: =C4/I4 | L4: =I4/(ε_c1cd) | M4: =I4*(K4-Z_s1) | N4: =I4*(K4-Z_s2) | O4: =E_s*M4 | P4: =E_s*N4 | Q4: =O4*A_s1 | R4: =P4*A_s2 | S4: =Q4*($K4-Z_s1) | T4: =R4*($K4-Z_s2) | U4: =(INDIRECT("a_"&U$2)/(U$2+1))*(($C4^(U$2+1)-$H4^(U$2+1))/(ε_c1cd^(U$2+1))) | V4: =(INDIRECT("a_"&V$2)/(V$2+1))*(($C4^(V$2+1)-$H4^(V$2+1))/(ε_c1cd^(V$2+1))) | W4: =(INDIRECT("a_"&W$2)/(W$2+1))*(($C4^(W$2+1)-$H4^(W$2+1))/(ε_c1cd^(W$2+1))) | X4: =(INDIRECT("a_"&X$2)/(X$2+1))*(($C4^(X$2+1)-$H4^(X$2+1))/(ε_c1cd^(X$2+1))) | Y4: =(INDIRECT("a_"&Y$2)/(Y$2+1))*(($C4^(Y$2+1)-$H4^(Y$2+1))/(ε_c1cd^(Y$2+1))) | Z4: =(INDIRECT("a_"&Z$2)/(Z$2+2))*(($C4^(Z$2+2)-$H4^(Z$2+2))/(ε_c1cd^(Z$2+2))) | AA4: =(INDIRECT("a_"&AA$2)/(AA$2+2))*(($C4^(AA$2+2)-$H4^(AA$2+2))/(ε_c1cd^(AA$2+2))) | AB4: =(INDIRECT("a_"&AB$2)/(AB$2+2))*(($C4^(AB$2+2)-$H4^(AB$2+2))/(ε_c1cd^(AB$2+2))) | AC4: =(INDIRECT("a_"&AC$2)/(AC$2+2))*(($C4^(AC$2+2)-$H4^(AC$2+2))/(ε_c1cd^(AC$2+2))) | AD4: =(INDIRECT("a_"&AD$2)/(AD$2+2))*(($C4^(AD$2+2)-$H4^(AD$2+2))/(ε_c1cd^(AD$2+2))) | AE4: =(b*f_cd/L4)*SUM(U4:Y4)+SUM(Q4:R4) | AF4: =AE4*(K4-y+e) | AG4: =(b*f_cd/(L4^2))*SUM(Z4:AD4)+SUM(S4:T4)-AF4 | AH4: =AG4<0 | AI4: =IF(A4=1,FALSE,(AND(AQ4,AH4,NOT(AI3)))) | AJ4: =(b*f_cd/L4)*(a_1/2*J4^2+a_2/3*J4^3+a_3/4*J4^4+a_4/5*J4^5+a_5/6*J4^6)+SUM(Q4:R4) | AK4: =AJ4*(K4-y+e) | AL4: =(b*f_cd/(L4^2))*(a_1/3*J4^3+a_2/4*J4^4+a_3/5*J4^5+a_4/6*J4^6+a_5/7*J4^7)+SUM(S4:T4)-AK4 | AM4: =AL4>0 | AN4: =IF(A4=1,FALSE,(AND(AQ4,AM4,NOT(AN3)))) | AO4: =IF(D4=1,AND(AH4,NOT(AI4)),AND(AM4,NOT(AN4))) | AP4: =IF(D4=1,AI4,AN4) | AQ4: =ABS(E4)<$AQ$2 | AS4: =IF(AP4,MAX(AS2:AS$3)+1,"")
A5: 3 | B5: =IF(A5=1,0,IF(AP5,0.1*ε_cu1cd,0)) | C5: =IF(A5=1,0.1*ε_cu1cd,C4+B4) | D5: =IF('Нормальний переріз'!$D$68>0,1,2) | E5: =IF(D5=1,F5,G5) | F5: =IF(AI4,0.11*ε_cu1cd,IF(AH4,F4*0.01,F4)) | G5: =IF(AP4,-0.1*ε_cu1cd,IF(AM4,G4*0.01,G4)) | H5: =IF(A5=1,E5,IF(AO4,H4-E4+E5,IF(AP4,0.8*H4,H4+E5))) | I5: =(C5-H5)/h | J5: =C5/(ε_c1cd) | K5: =C5/I5 | L5: =I5/(ε_c1cd) | M5: =I5*(K5-Z_s1) | N5: =I5*(K5-Z_s2) | O5: =E_s*M5 | P5: =E_s*N5 | Q5: =O5*A_s1 | R5: =P5*A_s2 | S5: =Q5*($K5-Z_s1) | T5: =R5*($K5-Z_s2) | U5: =(INDIRECT("a_"&U$2)/(U$2+1))*(($C5^(U$2+1)-$H5^(U$2+1))/(ε_c1cd^(U$2+1))) | V5: =(INDIRECT("a_"&V$2)/(V$2+1))*(($C5^(V$2+1)-$H5^(V$2+1))/(ε_c1cd^(V$2+1))) | W5: =(INDIRECT("a_"&W$2)/(W$2+1))*(($C5^(W$2+1)-$H5^(W$2+1))/(ε_c1cd^(W$2+1))) | X5: =(INDIRECT("a_"&X$2)/(X$2+1))*(($C5^(X$2+1)-$H5^(X$2+1))/(ε_c1cd^(X$2+1))) | Y5: =(INDIRECT("a_"&Y$2)/(Y$2+1))*(($C5^(Y$2+1)-$H5^(Y$2+1))/(ε_c1cd^(Y$2+1))) | Z5: =(INDIRECT("a_"&Z$2)/(Z$2+2))*(($C5^(Z$2+2)-$H5^(Z$2+2))/(ε_c1cd^(Z$2+2))) | AA5: =(INDIRECT("a_"&AA$2)/(AA$2+2))*(($C5^(AA$2+2)-$H5^(AA$2+2))/(ε_c1cd^(AA$2+2))) | AB5: =(INDIRECT("a_"&AB$2)/(AB$2+2))*(($C5^(AB$2+2)-$H5^(AB$2+2))/(ε_c1cd^(AB$2+2))) | AC5: =(INDIRECT("a_"&AC$2)/(AC$2+2))*(($C5^(AC$2+2)-$H5^(AC$2+2))/(ε_c1cd^(AC$2+2))) | AD5: =(INDIRECT("a_"&AD$2)/(AD$2+2))*(($C5^(AD$2+2)-$H5^(AD$2+2))/(ε_c1cd^(AD$2+2))) | AE5: =(b*f_cd/L5)*SUM(U5:Y5)+SUM(Q5:R5) | AF5: =AE5*(K5-y+e) | AG5: =(b*f_cd/(L5^2))*SUM(Z5:AD5)+SUM(S5:T5)-AF5 | AH5: =AG5<0 | AI5: =IF(A5=1,FALSE,(AND(AQ5,AH5,NOT(AI4)))) | AJ5: =(b*f_cd/L5)*(a_1/2*J5^2+a_2/3*J5^3+a_3/4*J5^4+a_4/5*J5^5+a_5/6*J5^6)+SUM(Q5:R5) | AK5: =AJ5*(K5-y+e) | AL5: =(b*f_cd/(L5^2))*(a_1/3*J5^3+a_2/4*J5^4+a_3/5*J5^5+a_4/6*J5^6+a_5/7*J5^7)+SUM(S5:T5)-AK5 | AM5: =AL5>0 | AN5: =IF(A5=1,FALSE,(AND(AQ5,AM5,NOT(AN4)))) | AO5: =IF(D5=1,AND(AH5,NOT(AI5)),AND(AM5,NOT(AN5))) | AP5: =IF(D5=1,AI5,AN5) | AQ5: =ABS(E5)<$AQ$2 | AS5: =IF(AP5,MAX(AS3:AS$3)+1,"")
A6: 4 | B6: =IF(A6=1,0,IF(AP6,0.1*ε_cu1cd,0)) | C6: =IF(A6=1,0.1*ε_cu1cd,C5+B5) | D6: =IF('Нормальний переріз'!$D$68>0,1,2) | E6: =IF(D6=1,F6,G6) | F6: =IF(AI5,0.11*ε_cu1cd,IF(AH5,F5*0.01,F5)) | G6: =IF(AP5,-0.1*ε_cu1cd,IF(AM5,G5*0.01,G5)) | H6: =IF(A6=1,E6,IF(AO5,H5-E5+E6,IF(AP5,0.8*H5,H5+E6))) | I6: =(C6-H6)/h | J6: =C6/(ε_c1cd) | K6: =C6/I6 | L6: =I6/(ε_c1cd) | M6: =I6*(K6-Z_s1) | N6: =I6*(K6-Z_s2) | O6: =E_s*M6 | P6: =E_s*N6 | Q6: =O6*A_s1 | R6: =P6*A_s2 | S6: =Q6*($K6-Z_s1) | T6: =R6*($K6-Z_s2) | U6: =(INDIRECT("a_"&U$2)/(U$2+1))*(($C6^(U$2+1)-$H6^(U$2+1))/(ε_c1cd^(U$2+1))) | V6: =(INDIRECT("a_"&V$2)/(V$2+1))*(($C6^(V$2+1)-$H6^(V$2+1))/(ε_c1cd^(V$2+1))) | W6: =(INDIRECT("a_"&W$2)/(W$2+1))*(($C6^(W$2+1)-$H6^(W$2+1))/(ε_c1cd^(W$2+1))) | X6: =(INDIRECT("a_"&X$2)/(X$2+1))*(($C6^(X$2+1)-$H6^(X$2+1))/(ε_c1cd^(X$2+1))) | Y6: =(INDIRECT("a_"&Y$2)/(Y$2+1))*(($C6^(Y$2+1)-$H6^(Y$2+1))/(ε_c1cd^(Y$2+1))) | Z6: =(INDIRECT("a_"&Z$2)/(Z$2+2))*(($C6^(Z$2+2)-$H6^(Z$2+2))/(ε_c1cd^(Z$2+2))) | AA6: =(INDIRECT("a_"&AA$2)/(AA$2+2))*(($C6^(AA$2+2)-$H6^(AA$2+2))/(ε_c1cd^(AA$2+2))) | AB6: =(INDIRECT("a_"&AB$2)/(AB$2+2))*(($C6^(AB$2+2)-$H6^(AB$2+2))/(ε_c1cd^(AB$2+2))) | AC6: =(INDIRECT("a_"&AC$2)/(AC$2+2))*(($C6^(AC$2+2)-$H6^(AC$2+2))/(ε_c1cd^(AC$2+2))) | AD6: =(INDIRECT("a_"&AD$2)/(AD$2+2))*(($C6^(AD$2+2)-$H6^(AD$2+2))/(ε_c1cd^(AD$2+2))) | AE6: =(b*f_cd/L6)*SUM(U6:Y6)+SUM(Q6:R6) | AF6: =AE6*(K6-y+e) | AG6: =(b*f_cd/(L6^2))*SUM(Z6:AD6)+SUM(S6:T6)-AF6 | AH6: =AG6<0 | AI6: =IF(A6=1,FALSE,(AND(AQ6,AH6,NOT(AI5)))) | AJ6: =(b*f_cd/L6)*(a_1/2*J6^2+a_2/3*J6^3+a_3/4*J6^4+a_4/5*J6^5+a_5/6*J6^6)+SUM(Q6:R6) | AK6: =AJ6*(K6-y+e) | AL6: =(b*f_cd/(L6^2))*(a_1/3*J6^3+a_2/4*J6^4+a_3/5*J6^5+a_4/6*J6^6+a_5/7*J6^7)+SUM(S6:T6)-AK6 | AM6: =AL6>0 | AN6: =IF(A6=1,FALSE,(AND(AQ6,AM6,NOT(AN5)))) | AO6: =IF(D6=1,AND(AH6,NOT(AI6)),AND(AM6,NOT(AN6))) | AP6: =IF(D6=1,AI6,AN6) | AQ6: =ABS(E6)<$AQ$2 | AS6: =IF(AP6,MAX(AS$3:AS4)+1,"")
A7: 5 | B7: =IF(A7=1,0,IF(AP7,0.1*ε_cu1cd,0)) | C7: 6.56e-05 | D7: =IF('Нормальний переріз'!$D$68>0,1,2) | E7: =IF(D7=1,F7,G7) | F7: =IF(AI6,0.11*ε_cu1cd,IF(AH6,F6*0.01,F6)) | G7: =IF(AP6,-0.1*ε_cu1cd,IF(AM6,G6*0.01,G6)) | H7: 5.42e-05 | I7: =(C7-H7)/h | J7: =C7/(ε_c1cd) | K7: =C7/I7 | L7: =I7/(ε_c1cd) | M7: =I7*(K7-Z_s1) | N7: =I7*(K7-Z_s2) | O7: =E_s*M7 | P7: =E_s*N7 | Q7: =O7*A_s1 | R7: =P7*A_s2 | S7: =Q7*($K7-Z_s1) | T7: =R7*($K7-Z_s2) | U7: =(INDIRECT("a_"&U$2)/(U$2+1))*(($C7^(U$2+1)-$H7^(U$2+1))/(ε_c1cd^(U$2+1))) | V7: =(INDIRECT("a_"&V$2)/(V$2+1))*(($C7^(V$2+1)-$H7^(V$2+1))/(ε_c1cd^(V$2+1))) | W7: =(INDIRECT("a_"&W$2)/(W$2+1))*(($C7^(W$2+1)-$H7^(W$2+1))/(ε_c1cd^(W$2+1))) | X7: =(INDIRECT("a_"&X$2)/(X$2+1))*(($C7^(X$2+1)-$H7^(X$2+1))/(ε_c1cd^(X$2+1))) | Y7: =(INDIRECT("a_"&Y$2)/(Y$2+1))*(($C7^(Y$2+1)-$H7^(Y$2+1))/(ε_c1cd^(Y$2+1))) | Z7: =(INDIRECT("a_"&Z$2)/(Z$2+2))*(($C7^(Z$2+2)-$H7^(Z$2+2))/(ε_c1cd^(Z$2+2))) | AA7: =(INDIRECT("a_"&AA$2)/(AA$2+2))*(($C7^(AA$2+2)-$H7^(AA$2+2))/(ε_c1cd^(AA$2+2))) | AB7: =(INDIRECT("a_"&AB$2)/(AB$2+2))*(($C7^(AB$2+2)-$H7^(AB$2+2))/(ε_c1cd^(AB$2+2))) | AC7: =(INDIRECT("a_"&AC$2)/(AC$2+2))*(($C7^(AC$2+2)-$H7^(AC$2+2))/(ε_c1cd^(AC$2+2))) | AD7: =(INDIRECT("a_"&AD$2)/(AD$2+2))*(($C7^(AD$2+2)-$H7^(AD$2+2))/(ε_c1cd^(AD$2+2))) | AE7: =(b*f_cd/L7)*SUM(U7:Y7)+SUM(Q7:R7) | AF7: =AE7*(K7-y+e) | AG7: =(b*f_cd/(L7^2))*SUM(Z7:AD7)+SUM(S7:T7)-AF7 | AH7: =AG7<0 | AI7: =IF(A7=1,FALSE,(AND(AQ7,AH7,NOT(AI6)))) | AJ7: =(b*f_cd/L7)*(a_1/2*J7^2+a_2/3*J7^3+a_3/4*J7^4+a_4/5*J7^5+a_5/6*J7^6)+SUM(Q7:R7) | AK7: =AJ7*(K7-y+e) | AL7: =(b*f_cd/(L7^2))*(a_1/3*J7^3+a_2/4*J7^4+a_3/5*J7^5+a_4/6*J7^6+a_5/7*J7^7)+SUM(S7:T7)-AK7 | AM7: =AL7>0 | AN7: =IF(A7=1,FALSE,(AND(AQ7,AM7,NOT(AN6)))) | AO7: =IF(D7=1,AND(AH7,NOT(AI7)),AND(AM7,NOT(AN7))) | AP7: =IF(D7=1,AI7,AN7) | AQ7: =ABS(E7)<$AQ$2 | AS7: =IF(AP7,MAX(AS$3:AS5)+1,"")
A8: 6 | B8: =IF(A8=1,0,IF(AP8,0.1*ε_cu1cd,0)) | C8: =IF(A8=1,0.1*ε_cu1cd,C7+B7) | D8: =IF('Нормальний переріз'!$D$68>0,1,2) | E8: =IF(D8=1,F8,G8) | F8: =IF(AI7,0.11*ε_cu1cd,IF(AH7,F7*0.01,F7)) | G8: =IF(AP7,-0.1*ε_cu1cd,IF(AM7,G7*0.01,G7)) | H8: =IF(A8=1,E8,IF(AO7,H7-E7+E8,IF(AP7,0.8*H7,H7+E8))) | I8: =(C8-H8)/h | J8: =C8/(ε_c1cd) | K8: =C8/I8 | L8: =I8/(ε_c1cd) | M8: =I8*(K8-Z_s1) | N8: =I8*(K8-Z_s2) | O8: =E_s*M8 | P8: =E_s*N8 | Q8: =O8*A_s1 | R8: =P8*A_s2 | S8: =Q8*($K8-Z_s1) | T8: =R8*($K8-Z_s2) | U8: =(INDIRECT("a_"&U$2)/(U$2+1))*(($C8^(U$2+1)-$H8^(U$2+1))/(ε_c1cd^(U$2+1))) | V8: =(INDIRECT("a_"&V$2)/(V$2+1))*(($C8^(V$2+1)-$H8^(V$2+1))/(ε_c1cd^(V$2+1))) | W8: =(INDIRECT("a_"&W$2)/(W$2+1))*(($C8^(W$2+1)-$H8^(W$2+1))/(ε_c1cd^(W$2+1))) | X8: =(INDIRECT("a_"&X$2)/(X$2+1))*(($C8^(X$2+1)-$H8^(X$2+1))/(ε_c1cd^(X$2+1))) | Y8: =(INDIRECT("a_"&Y$2)/(Y$2+1))*(($C8^(Y$2+1)-$H8^(Y$2+1))/(ε_c1cd^(Y$2+1))) | Z8: =(INDIRECT("a_"&Z$2)/(Z$2+2))*(($C8^(Z$2+2)-$H8^(Z$2+2))/(ε_c1cd^(Z$2+2))) | AA8: =(INDIRECT("a_"&AA$2)/(AA$2+2))*(($C8^(AA$2+2)-$H8^(AA$2+2))/(ε_c1cd^(AA$2+2))) | AB8: =(INDIRECT("a_"&AB$2)/(AB$2+2))*(($C8^(AB$2+2)-$H8^(AB$2+2))/(ε_c1cd^(AB$2+2))) | AC8: =(INDIRECT("a_"&AC$2)/(AC$2+2))*(($C8^(AC$2+2)-$H8^(AC$2+2))/(ε_c1cd^(AC$2+2))) | AD8: =(INDIRECT("a_"&AD$2)/(AD$2+2))*(($C8^(AD$2+2)-$H8^(AD$2+2))/(ε_c1cd^(AD$2+2))) | AE8: =(b*f_cd/L8)*SUM(U8:Y8)+SUM(Q8:R8) | AF8: =AE8*(K8-y+e) | AG8: =(b*f_cd/(L8^2))*SUM(Z8:AD8)+SUM(S8:T8)-AF8 | AH8: =AG8<0 | AI8: =IF(A8=1,FALSE,(AND(AQ8,AH8,NOT(AI7)))) | AJ8: =(b*f_cd/L8)*(a_1/2*J8^2+a_2/3*J8^3+a_3/4*J8^4+a_4/5*J8^5+a_5/6*J8^6)+SUM(Q8:R8) | AK8: =AJ8*(K8-y+e) | AL8: =(b*f_cd/(L8^2))*(a_1/3*J8^3+a_2/4*J8^4+a_3/5*J8^5+a_4/6*J8^6+a_5/7*J8^7)+SUM(S8:T8)-AK8 | AM8: =AL8>0 | AN8: =IF(A8=1,FALSE,(AND(AQ8,AM8,NOT(AN7)))) | AO8: =IF(D8=1,AND(AH8,NOT(AI8)),AND(AM8,NOT(AN8))) | AP8: =IF(D8=1,AI8,AN8) | AQ8: =ABS(E8)<$AQ$2 | AS8: =IF(AP8,MAX(AS$3:AS6)+1,"")
A9: 7 | B9: =IF(A9=1,0,IF(AP9,0.1*ε_cu1cd,0)) | C9: =IF(A9=1,0.1*ε_cu1cd,C8+B8) | D9: =IF('Нормальний переріз'!$D$68>0,1,2) | E9: =IF(D9=1,F9,G9) | F9: =IF(AI8,0.11*ε_cu1cd,IF(AH8,F8*0.01,F8)) | G9: =IF(AP8,-0.1*ε_cu1cd,IF(AM8,G8*0.01,G8)) | H9: =IF(A9=1,E9,IF(AO8,H8-E8+E9,IF(AP8,0.8*H8,H8+E9))) | I9: =(C9-H9)/h | J9: =C9/(ε_c1cd) | K9: =C9/I9 | L9: =I9/(ε_c1cd) | M9: =I9*(K9-Z_s1) | N9: =I9*(K9-Z_s2) | O9: =E_s*M9 | P9: =E_s*N9 | Q9: =O9*A_s1 | R9: =P9*A_s2 | S9: =Q9*($K9-Z_s1) | T9: =R9*($K9-Z_s2) | U9: =(INDIRECT("a_"&U$2)/(U$2+1))*(($C9^(U$2+1)-$H9^(U$2+1))/(ε_c1cd^(U$2+1))) | V9: =(INDIRECT("a_"&V$2)/(V$2+1))*(($C9^(V$2+1)-$H9^(V$2+1))/(ε_c1cd^(V$2+1))) | W9: =(INDIRECT("a_"&W$2)/(W$2+1))*(($C9^(W$2+1)-$H9^(W$2+1))/(ε_c1cd^(W$2+1))) | X9: =(INDIRECT("a_"&X$2)/(X$2+1))*(($C9^(X$2+1)-$H9^(X$2+1))/(ε_c1cd^(X$2+1))) | Y9: =(INDIRECT("a_"&Y$2)/(Y$2+1))*(($C9^(Y$2+1)-$H9^(Y$2+1))/(ε_c1cd^(Y$2+1))) | Z9: =(INDIRECT("a_"&Z$2)/(Z$2+2))*(($C9^(Z$2+2)-$H9^(Z$2+2))/(ε_c1cd^(Z$2+2))) | AA9: =(INDIRECT("a_"&AA$2)/(AA$2+2))*(($C9^(AA$2+2)-$H9^(AA$2+2))/(ε_c1cd^(AA$2+2))) | AB9: =(INDIRECT("a_"&AB$2)/(AB$2+2))*(($C9^(AB$2+2)-$H9^(AB$2+2))/(ε_c1cd^(AB$2+2))) | AC9: =(INDIRECT("a_"&AC$2)/(AC$2+2))*(($C9^(AC$2+2)-$H9^(AC$2+2))/(ε_c1cd^(AC$2+2))) | AD9: =(INDIRECT("a_"&AD$2)/(AD$2+2))*(($C9^(AD$2+2)-$H9^(AD$2+2))/(ε_c1cd^(AD$2+2))) | AE9: =(b*f_cd/L9)*SUM(U9:Y9)+SUM(Q9:R9) | AF9: =AE9*(K9-y+e) | AG9: =(b*f_cd/(L9^2))*SUM(Z9:AD9)+SUM(S9:T9)-AF9 | AH9: =AG9<0 | AI9: =IF(A9=1,FALSE,(AND(AQ9,AH9,NOT(AI8)))) | AJ9: =(b*f_cd/L9)*(a_1/2*J9^2+a_2/3*J9^3+a_3/4*J9^4+a_4/5*J9^5+a_5/6*J9^6)+SUM(Q9:R9) | AK9: =AJ9*(K9-y+e) | AL9: =(b*f_cd/(L9^2))*(a_1/3*J9^3+a_2/4*J9^4+a_3/5*J9^5+a_4/6*J9^6+a_5/7*J9^7)+SUM(S9:T9)-AK9 | AM9: =AL9>0 | AN9: =IF(A9=1,FALSE,(AND(AQ9,AM9,NOT(AN8)))) | AO9: =IF(D9=1,AND(AH9,NOT(AI9)),AND(AM9,NOT(AN9))) | AP9: =IF(D9=1,AI9,AN9) | AQ9: =ABS(E9)<$AQ$2 | AS9: =IF(AP9,MAX(AS$3:AS7)+1,"")
A10: 8 | B10: =IF(A10=1,0,IF(AP10,0.1*ε_cu1cd,0)) | C10: =IF(A10=1,0.1*ε_cu1cd,C9+B9) | D10: =IF('Нормальний переріз'!$D$68>0,1,2) | E10: =IF(D10=1,F10,G10) | F10: =IF(AI9,0.11*ε_cu1cd,IF(AH9,F9*0.01,F9)) | G10: =IF(AP9,-0.1*ε_cu1cd,IF(AM9,G9*0.01,G9)) | H10: =IF(A10=1,E10,IF(AO9,H9-E9+E10,IF(AP9,0.8*H9,H9+E10))) | I10: =(C10-H10)/h | J10: =C10/(ε_c1cd) | K10: =C10/I10 | L10: =I10/(ε_c1cd) | M10: =I10*(K10-Z_s1) | N10: =I10*(K10-Z_s2) | O10: =E_s*M10 | P10: =E_s*N10 | Q10: =O10*A_s1 | R10: =P10*A_s2 | S10: =Q10*($K10-Z_s1) | T10: =R10*($K10-Z_s2) | U10: =(INDIRECT("a_"&U$2)/(U$2+1))*(($C10^(U$2+1)-$H10^(U$2+1))/(ε_c1cd^(U$2+1))) | V10: =(INDIRECT("a_"&V$2)/(V$2+1))*(($C10^(V$2+1)-$H10^(V$2+1))/(ε_c1cd^(V$2+1))) | W10: =(INDIRECT("a_"&W$2)/(W$2+1))*(($C10^(W$2+1)-$H10^(W$2+1))/(ε_c1cd^(W$2+1))) | X10: =(INDIRECT("a_"&X$2)/(X$2+1))*(($C10^(X$2+1)-$H10^(X$2+1))/(ε_c1cd^(X$2+1))) | Y10: =(INDIRECT("a_"&Y$2)/(Y$2+1))*(($C10^(Y$2+1)-$H10^(Y$2+1))/(ε_c1cd^(Y$2+1))) | Z10: =(INDIRECT("a_"&Z$2)/(Z$2+2))*(($C10^(Z$2+2)-$H10^(Z$2+2))/(ε_c1cd^(Z$2+2))) | AA10: =(INDIRECT("a_"&AA$2)/(AA$2+2))*(($C10^(AA$2+2)-$H10^(AA$2+2))/(ε_c1cd^(AA$2+2))) | AB10: =(INDIRECT("a_"&AB$2)/(AB$2+2))*(($C10^(AB$2+2)-$H10^(AB$2+2))/(ε_c1cd^(AB$2+2))) | AC10: =(INDIRECT("a_"&AC$2)/(AC$2+2))*(($C10^(AC$2+2)-$H10^(AC$2+2))/(ε_c1cd^(AC$2+2))) | AD10: =(INDIRECT("a_"&AD$2)/(AD$2+2))*(($C10^(AD$2+2)-$H10^(AD$2+2))/(ε_c1cd^(AD$2+2))) | AE10: =(b*f_cd/L10)*SUM(U10:Y10)+SUM(Q10:R10) | AF10: =AE10*(K10-y+e) | AG10: =(b*f_cd/(L10^2))*SUM(Z10:AD10)+SUM(S10:T10)-AF10 | AH10: =AG10<0 | AI10: =IF(A10=1,FALSE,(AND(AQ10,AH10,NOT(AI9)))) | AJ10: =(b*f_cd/L10)*(a_1/2*J10^2+a_2/3*J10^3+a_3/4*J10^4+a_4/5*J10^5+a_5/6*J10^6)+SUM(Q10:R10) | AK10: =AJ10*(K10-y+e) | AL10: =(b*f_cd/(L10^2))*(a_1/3*J10^3+a_2/4*J10^4+a_3/5*J10^5+a_4/6*J10^6+a_5/7*J10^7)+SUM(S10:T10)-AK10 | AM10: =AL10>0 | AN10: =IF(A10=1,FALSE,(AND(AQ10,AM10,NOT(AN9)))) | AO10: =IF(D10=1,AND(AH10,NOT(AI10)),AND(AM10,NOT(AN10))) | AP10: =IF(D10=1,AI10,AN10) | AQ10: =ABS(E10)<$AQ$2 | AS10: =IF(AP10,MAX(AS$3:AS8)+1,"")
A11: 9 | B11: =IF(A11=1,0,IF(AP11,0.1*ε_cu1cd,0)) | C11: =IF(A11=1,0.1*ε_cu1cd,C10+B10) | D11: =IF('Нормальний переріз'!$D$68>0,1,2) | E11: =IF(D11=1,F11,G11) | F11: =IF(AI10,0.11*ε_cu1cd,IF(AH10,F10*0.01,F10)) | G11: =IF(AP10,-0.1*ε_cu1cd,IF(AM10,G10*0.01,G10)) | H11: =IF(A11=1,E11,IF(AO10,H10-E10+E11,IF(AP10,0.8*H10,H10+E11))) | I11: =(C11-H11)/h | J11: =C11/(ε_c1cd) | K11: =C11/I11 | L11: =I11/(ε_c1cd) | M11: =I11*(K11-Z_s1) | N11: =I11*(K11-Z_s2) | O11: =E_s*M11 | P11: =E_s*N11 | Q11: =O11*A_s1 | R11: =P11*A_s2 | S11: =Q11*($K11-Z_s1) | T11: =R11*($K11-Z_s2) | U11: =(INDIRECT("a_"&U$2)/(U$2+1))*(($C11^(U$2+1)-$H11^(U$2+1))/(ε_c1cd^(U$2+1))) | V11: =(INDIRECT("a_"&V$2)/(V$2+1))*(($C11^(V$2+1)-$H11^(V$2+1))/(ε_c1cd^(V$2+1))) | W11: =(INDIRECT("a_"&W$2)/(W$2+1))*(($C11^(W$2+1)-$H11^(W$2+1))/(ε_c1cd^(W$2+1))) | X11: =(INDIRECT("a_"&X$2)/(X$2+1))*(($C11^(X$2+1)-$H11^(X$2+1))/(ε_c1cd^(X$2+1))) | Y11: =(INDIRECT("a_"&Y$2)/(Y$2+1))*(($C11^(Y$2+1)-$H11^(Y$2+1))/(ε_c1cd^(Y$2+1))) | Z11: =(INDIRECT("a_"&Z$2)/(Z$2+2))*(($C11^(Z$2+2)-$H11^(Z$2+2))/(ε_c1cd^(Z$2+2))) | AA11: =(INDIRECT("a_"&AA$2)/(AA$2+2))*(($C11^(AA$2+2)-$H11^(AA$2+2))/(ε_c1cd^(AA$2+2))) | AB11: =(INDIRECT("a_"&AB$2)/(AB$2+2))*(($C11^(AB$2+2)-$H11^(AB$2+2))/(ε_c1cd^(AB$2+2))) | AC11: =(INDIRECT("a_"&AC$2)/(AC$2+2))*(($C11^(AC$2+2)-$H11^(AC$2+2))/(ε_c1cd^(AC$2+2))) | AD11: =(INDIRECT("a_"&AD$2)/(AD$2+2))*(($C11^(AD$2+2)-$H11^(AD$2+2))/(ε_c1cd^(AD$2+2))) | AE11: =(b*f_cd/L11)*SUM(U11:Y11)+SUM(Q11:R11) | AF11: =AE11*(K11-y+e) | AG11: =(b*f_cd/(L11^2))*SUM(Z11:AD11)+SUM(S11:T11)-AF11 | AH11: =AG11<0 | AI11: =IF(A11=1,FALSE,(AND(AQ11,AH11,NOT(AI10)))) | AJ11: =(b*f_cd/L11)*(a_1/2*J11^2+a_2/3*J11^3+a_3/4*J11^4+a_4/5*J11^5+a_5/6*J11^6)+SUM(Q11:R11) | AK11: =AJ11*(K11-y+e) | AL11: =(b*f_cd/(L11^2))*(a_1/3*J11^3+a_2/4*J11^4+a_3/5*J11^5+a_4/6*J11^6+a_5/7*J11^7)+SUM(S11:T11)-AK11 | AM11: =AL11>0 | AN11: =IF(A11=1,FALSE,(AND(AQ11,AM11,NOT(AN10)))) | AO11: =IF(D11=1,AND(AH11,NOT(AI11)),AND(AM11,NOT(AN11))) | AP11: =IF(D11=1,AI11,AN11) | AQ11: =ABS(E11)<$AQ$2 | AS11: =IF(AP11,MAX(AS$3:AS9)+1,"")
A12: 10 | B12: =IF(A12=1,0,IF(AP12,0.1*ε_cu1cd,0)) | C12: =IF(A12=1,0.1*ε_cu1cd,C11+B11) | D12: =IF('Нормальний переріз'!$D$68>0,1,2) | E12: =IF(D12=1,F12,G12) | F12: =IF(AI11,0.11*ε_cu1cd,IF(AH11,F11*0.01,F11)) | G12: =IF(AP11,-0.1*ε_cu1cd,IF(AM11,G11*0.01,G11)) | H12: =IF(A12=1,E12,IF(AO11,H11-E11+E12,IF(AP11,0.8*H11,H11+E12))) | I12: =(C12-H12)/h | J12: =C12/(ε_c1cd) | K12: =C12/I12 | L12: =I12/(ε_c1cd) | M12: =I12*(K12-Z_s1) | N12: =I12*(K12-Z_s2) | O12: =E_s*M12 | P12: =E_s*N12 | Q12: =O12*A_s1 | R12: =P12*A_s2 | S12: =Q12*($K12-Z_s1) | T12: =R12*($K12-Z_s2) | U12: =(INDIRECT("a_"&U$2)/(U$2+1))*(($C12^(U$2+1)-$H12^(U$2+1))/(ε_c1cd^(U$2+1))) | V12: =(INDIRECT("a_"&V$2)/(V$2+1))*(($C12^(V$2+1)-$H12^(V$2+1))/(ε_c1cd^(V$2+1))) | W12: =(INDIRECT("a_"&W$2)/(W$2+1))*(($C12^(W$2+1)-$H12^(W$2+1))/(ε_c1cd^(W$2+1))) | X12: =(INDIRECT("a_"&X$2)/(X$2+1))*(($C12^(X$2+1)-$H12^(X$2+1))/(ε_c1cd^(X$2+1))) | Y12: =(INDIRECT("a_"&Y$2)/(Y$2+1))*(($C12^(Y$2+1)-$H12^(Y$2+1))/(ε_c1cd^(Y$2+1))) | Z12: =(INDIRECT("a_"&Z$2)/(Z$2+2))*(($C12^(Z$2+2)-$H12^(Z$2+2))/(ε_c1cd^(Z$2+2))) | AA12: =(INDIRECT("a_"&AA$2)/(AA$2+2))*(($C12^(AA$2+2)-$H12^(AA$2+2))/(ε_c1cd^(AA$2+2))) | AB12: =(INDIRECT("a_"&AB$2)/(AB$2+2))*(($C12^(AB$2+2)-$H12^(AB$2+2))/(ε_c1cd^(AB$2+2))) | AC12: =(INDIRECT("a_"&AC$2)/(AC$2+2))*(($C12^(AC$2+2)-$H12^(AC$2+2))/(ε_c1cd^(AC$2+2))) | AD12: =(INDIRECT("a_"&AD$2)/(AD$2+2))*(($C12^(AD$2+2)-$H12^(AD$2+2))/(ε_c1cd^(AD$2+2))) | AE12: =(b*f_cd/L12)*SUM(U12:Y12)+SUM(Q12:R12) | AF12: =AE12*(K12-y+e) | AG12: =(b*f_cd/(L12^2))*SUM(Z12:AD12)+SUM(S12:T12)-AF12 | AH12: =AG12<0 | AI12: =IF(A12=1,FALSE,(AND(AQ12,AH12,NOT(AI11)))) | AJ12: =(b*f_cd/L12)*(a_1/2*J12^2+a_2/3*J12^3+a_3/4*J12^4+a_4/5*J12^5+a_5/6*J12^6)+SUM(Q12:R12) | AK12: =AJ12*(K12-y+e) | AL12: =(b*f_cd/(L12^2))*(a_1/3*J12^3+a_2/4*J12^4+a_3/5*J12^5+a_4/6*J12^6+a_5/7*J12^7)+SUM(S12:T12)-AK12 | AM12: =AL12>0 | AN12: =IF(A12=1,FALSE,(AND(AQ12,AM12,NOT(AN11)))) | AO12: =IF(D12=1,AND(AH12,NOT(AI12)),AND(AM12,NOT(AN12))) | AP12: =IF(D12=1,AI12,AN12) | AQ12: =ABS(E12)<$AQ$2 | AS12: =IF(AP12,MAX(AS$3:AS10)+1,"")
A13: 11 | B13: =IF(A13=1,0,IF(AP13,0.1*ε_cu1cd,0)) | C13: =IF(A13=1,0.1*ε_cu1cd,C12+B12) | D13: =IF('Нормальний переріз'!$D$68>0,1,2) | E13: =IF(D13=1,F13,G13) | F13: =IF(AI12,0.11*ε_cu1cd,IF(AH12,F12*0.01,F12)) | G13: =IF(AP12,-0.1*ε_cu1cd,IF(AM12,G12*0.01,G12)) | H13: =IF(A13=1,E13,IF(AO12,H12-E12+E13,IF(AP12,0.8*H12,H12+E13))) | I13: =(C13-H13)/h | J13: =C13/(ε_c1cd) | K13: =C13/I13 | L13: =I13/(ε_c1cd) | M13: =I13*(K13-Z_s1) | N13: =I13*(K13-Z_s2) | O13: =E_s*M13 | P13: =E_s*N13 | Q13: =O13*A_s1 | R13: =P13*A_s2 | S13: =Q13*($K13-Z_s1) | T13: =R13*($K13-Z_s2) | U13: =(INDIRECT("a_"&U$2)/(U$2+1))*(($C13^(U$2+1)-$H13^(U$2+1))/(ε_c1cd^(U$2+1))) | V13: =(INDIRECT("a_"&V$2)/(V$2+1))*(($C13^(V$2+1)-$H13^(V$2+1))/(ε_c1cd^(V$2+1))) | W13: =(INDIRECT("a_"&W$2)/(W$2+1))*(($C13^(W$2+1)-$H13^(W$2+1))/(ε_c1cd^(W$2+1))) | X13: =(INDIRECT("a_"&X$2)/(X$2+1))*(($C13^(X$2+1)-$H13^(X$2+1))/(ε_c1cd^(X$2+1))) | Y13: =(INDIRECT("a_"&Y$2)/(Y$2+1))*(($C13^(Y$2+1)-$H13^(Y$2+1))/(ε_c1cd^(Y$2+1))) | Z13: =(INDIRECT("a_"&Z$2)/(Z$2+2))*(($C13^(Z$2+2)-$H13^(Z$2+2))/(ε_c1cd^(Z$2+2))) | AA13: =(INDIRECT("a_"&AA$2)/(AA$2+2))*(($C13^(AA$2+2)-$H13^(AA$2+2))/(ε_c1cd^(AA$2+2))) | AB13: =(INDIRECT("a_"&AB$2)/(AB$2+2))*(($C13^(AB$2+2)-$H13^(AB$2+2))/(ε_c1cd^(AB$2+2))) | AC13: =(INDIRECT("a_"&AC$2)/(AC$2+2))*(($C13^(AC$2+2)-$H13^(AC$2+2))/(ε_c1cd^(AC$2+2))) | AD13: =(INDIRECT("a_"&AD$2)/(AD$2+2))*(($C13^(AD$2+2)-$H13^(AD$2+2))/(ε_c1cd^(AD$2+2))) | AE13: =(b*f_cd/L13)*SUM(U13:Y13)+SUM(Q13:R13) | AF13: =AE13*(K13-y+e) | AG13: =(b*f_cd/(L13^2))*SUM(Z13:AD13)+SUM(S13:T13)-AF13 | AH13: =AG13<0 | AI13: =IF(A13=1,FALSE,(AND(AQ13,AH13,NOT(AI12)))) | AJ13: =(b*f_cd/L13)*(a_1/2*J13^2+a_2/3*J13^3+a_3/4*J13^4+a_4/5*J13^5+a_5/6*J13^6)+SUM(Q13:R13) | AK13: =AJ13*(K13-y+e) | AL13: =(b*f_cd/(L13^2))*(a_1/3*J13^3+a_2/4*J13^4+a_3/5*J13^5+a_4/6*J13^6+a_5/7*J13^7)+SUM(S13:T13)-AK13 | AM13: =AL13>0 | AN13: =IF(A13=1,FALSE,(AND(AQ13,AM13,NOT(AN12)))) | AO13: =IF(D13=1,AND(AH13,NOT(AI13)),AND(AM13,NOT(AN13))) | AP13: =IF(D13=1,AI13,AN13) | AQ13: =ABS(E13)<$AQ$2 | AS13: =IF(AP13,MAX(AS$3:AS11)+1,"")
A14: 12 | B14: =IF(A14=1,0,IF(AP14,0.1*ε_cu1cd,0)) | C14: =IF(A14=1,0.1*ε_cu1cd,C13+B13) | D14: =IF('Нормальний переріз'!$D$68>0,1,2) | E14: =IF(D14=1,F14,G14) | F14: =IF(AI13,0.11*ε_cu1cd,IF(AH13,F13*0.01,F13)) | G14: =IF(AP13,-0.1*ε_cu1cd,IF(AM13,G13*0.01,G13)) | H14: =IF(A14=1,E14,IF(AO13,H13-E13+E14,IF(AP13,0.8*H13,H13+E14))) | I14: =(C14-H14)/h | J14: =C14/(ε_c1cd) | K14: =C14/I14 | L14: =I14/(ε_c1cd) | M14: =I14*(K14-Z_s1) | N14: =I14*(K14-Z_s2) | O14: =E_s*M14 | P14: =E_s*N14 | Q14: =O14*A_s1 | R14: =P14*A_s2 | S14: =Q14*($K14-Z_s1) | T14: =R14*($K14-Z_s2) | U14: =(INDIRECT("a_"&U$2)/(U$2+1))*(($C14^(U$2+1)-$H14^(U$2+1))/(ε_c1cd^(U$2+1))) | V14: =(INDIRECT("a_"&V$2)/(V$2+1))*(($C14^(V$2+1)-$H14^(V$2+1))/(ε_c1cd^(V$2+1))) | W14: =(INDIRECT("a_"&W$2)/(W$2+1))*(($C14^(W$2+1)-$H14^(W$2+1))/(ε_c1cd^(W$2+1))) | X14: =(INDIRECT("a_"&X$2)/(X$2+1))*(($C14^(X$2+1)-$H14^(X$2+1))/(ε_c1cd^(X$2+1))) | Y14: =(INDIRECT("a_"&Y$2)/(Y$2+1))*(($C14^(Y$2+1)-$H14^(Y$2+1))/(ε_c1cd^(Y$2+1))) | Z14: =(INDIRECT("a_"&Z$2)/(Z$2+2))*(($C14^(Z$2+2)-$H14^(Z$2+2))/(ε_c1cd^(Z$2+2))) | AA14: =(INDIRECT("a_"&AA$2)/(AA$2+2))*(($C14^(AA$2+2)-$H14^(AA$2+2))/(ε_c1cd^(AA$2+2))) | AB14: =(INDIRECT("a_"&AB$2)/(AB$2+2))*(($C14^(AB$2+2)-$H14^(AB$2+2))/(ε_c1cd^(AB$2+2))) | AC14: =(INDIRECT("a_"&AC$2)/(AC$2+2))*(($C14^(AC$2+2)-$H14^(AC$2+2))/(ε_c1cd^(AC$2+2))) | AD14: =(INDIRECT("a_"&AD$2)/(AD$2+2))*(($C14^(AD$2+2)-$H14^(AD$2+2))/(ε_c1cd^(AD$2+2))) | AE14: =(b*f_cd/L14)*SUM(U14:Y14)+SUM(Q14:R14) | AF14: =AE14*(K14-y+e) | AG14: =(b*f_cd/(L14^2))*SUM(Z14:AD14)+SUM(S14:T14)-AF14 | AH14: =AG14<0 | AI14: =IF(A14=1,FALSE,(AND(AQ14,AH14,NOT(AI13)))) | AJ14: =(b*f_cd/L14)*(a_1/2*J14^2+a_2/3*J14^3+a_3/4*J14^4+a_4/5*J14^5+a_5/6*J14^6)+SUM(Q14:R14) | AK14: =AJ14*(K14-y+e) | AL14: =(b*f_cd/(L14^2))*(a_1/3*J14^3+a_2/4*J14^4+a_3/5*J14^5+a_4/6*J14^6+a_5/7*J14^7)+SUM(S14:T14)-AK14 | AM14: =AL14>0 | AN14: =IF(A14=1,FALSE,(AND(AQ14,AM14,NOT(AN13)))) | AO14: =IF(D14=1,AND(AH14,NOT(AI14)),AND(AM14,NOT(AN14))) | AP14: =IF(D14=1,AI14,AN14) | AQ14: =ABS(E14)<$AQ$2 | AS14: =IF(AP14,MAX(AS$3:AS12)+1,"")
A15: 13 | B15: =IF(A15=1,0,IF(AP15,0.1*ε_cu1cd,0)) | C15: =IF(A15=1,0.1*ε_cu1cd,C14+B14) | D15: =IF('Нормальний переріз'!$D$68>0,1,2) | E15: =IF(D15=1,F15,G15) | F15: =IF(AI14,0.11*ε_cu1cd,IF(AH14,F14*0.01,F14)) | G15: =IF(AP14,-0.1*ε_cu1cd,IF(AM14,G14*0.01,G14)) | H15: =IF(A15=1,E15,IF(AO14,H14-E14+E15,IF(AP14,0.8*H14,H14+E15))) | I15: =(C15-H15)/h | J15: =C15/(ε_c1cd) | K15: =C15/I15 | L15: =I15/(ε_c1cd) | M15: =I15*(K15-Z_s1) | N15: =I15*(K15-Z_s2) | O15: =E_s*M15 | P15: =E_s*N15 | Q15: =O15*A_s1 | R15: =P15*A_s2 | S15: =Q15*($K15-Z_s1) | T15: =R15*($K15-Z_s2) | U15: =(INDIRECT("a_"&U$2)/(U$2+1))*(($C15^(U$2+1)-$H15^(U$2+1))/(ε_c1cd^(U$2+1))) | V15: =(INDIRECT("a_"&V$2)/(V$2+1))*(($C15^(V$2+1)-$H15^(V$2+1))/(ε_c1cd^(V$2+1))) | W15: =(INDIRECT("a_"&W$2)/(W$2+1))*(($C15^(W$2+1)-$H15^(W$2+1))/(ε_c1cd^(W$2+1))) | X15: =(INDIRECT("a_"&X$2)/(X$2+1))*(($C15^(X$2+1)-$H15^(X$2+1))/(ε_c1cd^(X$2+1))) | Y15: =(INDIRECT("a_"&Y$2)/(Y$2+1))*(($C15^(Y$2+1)-$H15^(Y$2+1))/(ε_c1cd^(Y$2+1))) | Z15: =(INDIRECT("a_"&Z$2)/(Z$2+2))*(($C15^(Z$2+2)-$H15^(Z$2+2))/(ε_c1cd^(Z$2+2))) | AA15: =(INDIRECT("a_"&AA$2)/(AA$2+2))*(($C15^(AA$2+2)-$H15^(AA$2+2))/(ε_c1cd^(AA$2+2))) | AB15: =(INDIRECT("a_"&AB$2)/(AB$2+2))*(($C15^(AB$2+2)-$H15^(AB$2+2))/(ε_c1cd^(AB$2+2))) | AC15: =(INDIRECT("a_"&AC$2)/(AC$2+2))*(($C15^(AC$2+2)-$H15^(AC$2+2))/(ε_c1cd^(AC$2+2))) | AD15: =(INDIRECT("a_"&AD$2)/(AD$2+2))*(($C15^(AD$2+2)-$H15^(AD$2+2))/(ε_c1cd^(AD$2+2))) | AE15: =(b*f_cd/L15)*SUM(U15:Y15)+SUM(Q15:R15) | AF15: =AE15*(K15-y+e) | AG15: =(b*f_cd/(L15^2))*SUM(Z15:AD15)+SUM(S15:T15)-AF15 | AH15: =AG15<0 | AI15: =IF(A15=1,FALSE,(AND(AQ15,AH15,NOT(AI14)))) | AJ15: =(b*f_cd/L15)*(a_1/2*J15^2+a_2/3*J15^3+a_3/4*J15^4+a_4/5*J15^5+a_5/6*J15^6)+SUM(Q15:R15) | AK15: =AJ15*(K15-y+e) | AL15: =(b*f_cd/(L15^2))*(a_1/3*J15^3+a_2/4*J15^4+a_3/5*J15^5+a_4/6*J15^6+a_5/7*J15^7)+SUM(S15:T15)-AK15 | AM15: =AL15>0 | AN15: =IF(A15=1,FALSE,(AND(AQ15,AM15,NOT(AN14)))) | AO15: =IF(D15=1,AND(AH15,NOT(AI15)),AND(AM15,NOT(AN15))) | AP15: =IF(D15=1,AI15,AN15) | AQ15: =ABS(E15)<$AQ$2 | AS15: =IF(AP15,MAX(AS$3:AS13)+1,"")
A16: 14 | B16: =IF(A16=1,0,IF(AP16,0.1*ε_cu1cd,0)) | C16: =IF(A16=1,0.1*ε_cu1cd,C15+B15) | D16: =IF('Нормальний переріз'!$D$68>0,1,2) | E16: =IF(D16=1,F16,G16) | F16: =IF(AI15,0.11*ε_cu1cd,IF(AH15,F15*0.01,F15)) | G16: =IF(AP15,-0.1*ε_cu1cd,IF(AM15,G15*0.01,G15)) | H16: =IF(A16=1,E16,IF(AO15,H15-E15+E16,IF(AP15,0.8*H15,H15+E16))) | I16: =(C16-H16)/h | J16: =C16/(ε_c1cd) | K16: =C16/I16 | L16: =I16/(ε_c1cd) | M16: =I16*(K16-Z_s1) | N16: =I16*(K16-Z_s2) | O16: =E_s*M16 | P16: =E_s*N16 | Q16: =O16*A_s1 | R16: =P16*A_s2 | S16: =Q16*($K16-Z_s1) | T16: =R16*($K16-Z_s2) | U16: =(INDIRECT("a_"&U$2)/(U$2+1))*(($C16^(U$2+1)-$H16^(U$2+1))/(ε_c1cd^(U$2+1))) | V16: =(INDIRECT("a_"&V$2)/(V$2+1))*(($C16^(V$2+1)-$H16^(V$2+1))/(ε_c1cd^(V$2+1))) | W16: =(INDIRECT("a_"&W$2)/(W$2+1))*(($C16^(W$2+1)-$H16^(W$2+1))/(ε_c1cd^(W$2+1))) | X16: =(INDIRECT("a_"&X$2)/(X$2+1))*(($C16^(X$2+1)-$H16^(X$2+1))/(ε_c1cd^(X$2+1))) | Y16: =(INDIRECT("a_"&Y$2)/(Y$2+1))*(($C16^(Y$2+1)-$H16^(Y$2+1))/(ε_c1cd^(Y$2+1))) | Z16: =(INDIRECT("a_"&Z$2)/(Z$2+2))*(($C16^(Z$2+2)-$H16^(Z$2+2))/(ε_c1cd^(Z$2+2))) | AA16: =(INDIRECT("a_"&AA$2)/(AA$2+2))*(($C16^(AA$2+2)-$H16^(AA$2+2))/(ε_c1cd^(AA$2+2))) | AB16: =(INDIRECT("a_"&AB$2)/(AB$2+2))*(($C16^(AB$2+2)-$H16^(AB$2+2))/(ε_c1cd^(AB$2+2))) | AC16: =(INDIRECT("a_"&AC$2)/(AC$2+2))*(($C16^(AC$2+2)-$H16^(AC$2+2))/(ε_c1cd^(AC$2+2))) | AD16: =(INDIRECT("a_"&AD$2)/(AD$2+2))*(($C16^(AD$2+2)-$H16^(AD$2+2))/(ε_c1cd^(AD$2+2))) | AE16: =(b*f_cd/L16)*SUM(U16:Y16)+SUM(Q16:R16) | AF16: =AE16*(K16-y+e) | AG16: =(b*f_cd/(L16^2))*SUM(Z16:AD16)+SUM(S16:T16)-AF16 | AH16: =AG16<0 | AI16: =IF(A16=1,FALSE,(AND(AQ16,AH16,NOT(AI15)))) | AJ16: =(b*f_cd/L16)*(a_1/2*J16^2+a_2/3*J16^3+a_3/4*J16^4+a_4/5*J16^5+a_5/6*J16^6)+SUM(Q16:R16) | AK16: =AJ16*(K16-y+e) | AL16: =(b*f_cd/(L16^2))*(a_1/3*J16^3+a_2/4*J16^4+a_3/5*J16^5+a_4/6*J16^6+a_5/7*J16^7)+SUM(S16:T16)-AK16 | AM16: =AL16>0 | AN16: =IF(A16=1,FALSE,(AND(AQ16,AM16,NOT(AN15)))) | AO16: =IF(D16=1,AND(AH16,NOT(AI16)),AND(AM16,NOT(AN16))) | AP16: =IF(D16=1,AI16,AN16) | AQ16: =ABS(E16)<$AQ$2 | AS16: =IF(AP16,MAX(AS$3:AS14)+1,"")
A17: 15 | B17: =IF(A17=1,0,IF(AP17,0.1*ε_cu1cd,0)) | C17: =IF(A17=1,0.1*ε_cu1cd,C16+B16) | D17: =IF('Нормальний переріз'!$D$68>0,1,2) | E17: =IF(D17=1,F17,G17) | F17: =IF(AI16,0.11*ε_cu1cd,IF(AH16,F16*0.01,F16)) | G17: =IF(AP16,-0.1*ε_cu1cd,IF(AM16,G16*0.01,G16)) | H17: =IF(A17=1,E17,IF(AO16,H16-E16+E17,IF(AP16,0.8*H16,H16+E17))) | I17: =(C17-H17)/h | J17: =C17/(ε_c1cd) | K17: =C17/I17 | L17: =I17/(ε_c1cd) | M17: =I17*(K17-Z_s1) | N17: =I17*(K17-Z_s2) | O17: =E_s*M17 | P17: =E_s*N17 | Q17: =O17*A_s1 | R17: =P17*A_s2 | S17: =Q17*($K17-Z_s1) | T17: =R17*($K17-Z_s2) | U17: =(INDIRECT("a_"&U$2)/(U$2+1))*(($C17^(U$2+1)-$H17^(U$2+1))/(ε_c1cd^(U$2+1))) | V17: =(INDIRECT("a_"&V$2)/(V$2+1))*(($C17^(V$2+1)-$H17^(V$2+1))/(ε_c1cd^(V$2+1))) | W17: =(INDIRECT("a_"&W$2)/(W$2+1))*(($C17^(W$2+1)-$H17^(W$2+1))/(ε_c1cd^(W$2+1))) | X17: =(INDIRECT("a_"&X$2)/(X$2+1))*(($C17^(X$2+1)-$H17^(X$2+1))/(ε_c1cd^(X$2+1))) | Y17: =(INDIRECT("a_"&Y$2)/(Y$2+1))*(($C17^(Y$2+1)-$H17^(Y$2+1))/(ε_c1cd^(Y$2+1))) | Z17: =(INDIRECT("a_"&Z$2)/(Z$2+2))*(($C17^(Z$2+2)-$H17^(Z$2+2))/(ε_c1cd^(Z$2+2))) | AA17: =(INDIRECT("a_"&AA$2)/(AA$2+2))*(($C17^(AA$2+2)-$H17^(AA$2+2))/(ε_c1cd^(AA$2+2))) | AB17: =(INDIRECT("a_"&AB$2)/(AB$2+2))*(($C17^(AB$2+2)-$H17^(AB$2+2))/(ε_c1cd^(AB$2+2))) | AC17: =(INDIRECT("a_"&AC$2)/(AC$2+2))*(($C17^(AC$2+2)-$H17^(AC$2+2))/(ε_c1cd^(AC$2+2))) | AD17: =(INDIRECT("a_"&AD$2)/(AD$2+2))*(($C17^(AD$2+2)-$H17^(AD$2+2))/(ε_c1cd^(AD$2+2))) | AE17: =(b*f_cd/L17)*SUM(U17:Y17)+SUM(Q17:R17) | AF17: =AE17*(K17-y+e) | AG17: =(b*f_cd/(L17^2))*SUM(Z17:AD17)+SUM(S17:T17)-AF17 | AH17: =AG17<0 | AI17: =IF(A17=1,FALSE,(AND(AQ17,AH17,NOT(AI16)))) | AJ17: =(b*f_cd/L17)*(a_1/2*J17^2+a_2/3*J17^3+a_3/4*J17^4+a_4/5*J17^5+a_5/6*J17^6)+SUM(Q17:R17) | AK17: =AJ17*(K17-y+e) | AL17: =(b*f_cd/(L17^2))*(a_1/3*J17^3+a_2/4*J17^4+a_3/5*J17^5+a_4/6*J17^6+a_5/7*J17^7)+SUM(S17:T17)-AK17 | AM17: =AL17>0 | AN17: =IF(A17=1,FALSE,(AND(AQ17,AM17,NOT(AN16)))) | AO17: =IF(D17=1,AND(AH17,NOT(AI17)),AND(AM17,NOT(AN17))) | AP17: =IF(D17=1,AI17,AN17) | AQ17: =ABS(E17)<$AQ$2 | AS17: =IF(AP17,MAX(AS$3:AS15)+1,"")
A18: 16 | B18: =IF(A18=1,0,IF(AP18,0.1*ε_cu1cd,0)) | C18: =IF(A18=1,0.1*ε_cu1cd,C17+B17) | D18: =IF('Нормальний переріз'!$D$68>0,1,2) | E18: =IF(D18=1,F18,G18) | F18: =IF(AI17,0.11*ε_cu1cd,IF(AH17,F17*0.01,F17)) | G18: =IF(AP17,-0.1*ε_cu1cd,IF(AM17,G17*0.01,G17)) | H18: =IF(A18=1,E18,IF(AO17,H17-E17+E18,IF(AP17,0.8*H17,H17+E18))) | I18: =(C18-H18)/h | J18: =C18/(ε_c1cd) | K18: =C18/I18 | L18: =I18/(ε_c1cd) | M18: =I18*(K18-Z_s1) | N18: =I18*(K18-Z_s2) | O18: =E_s*M18 | P18: =E_s*N18 | Q18: =O18*A_s1 | R18: =P18*A_s2 | S18: =Q18*($K18-Z_s1) | T18: =R18*($K18-Z_s2) | U18: =(INDIRECT("a_"&U$2)/(U$2+1))*(($C18^(U$2+1)-$H18^(U$2+1))/(ε_c1cd^(U$2+1))) | V18: =(INDIRECT("a_"&V$2)/(V$2+1))*(($C18^(V$2+1)-$H18^(V$2+1))/(ε_c1cd^(V$2+1))) | W18: =(INDIRECT("a_"&W$2)/(W$2+1))*(($C18^(W$2+1)-$H18^(W$2+1))/(ε_c1cd^(W$2+1))) | X18: =(INDIRECT("a_"&X$2)/(X$2+1))*(($C18^(X$2+1)-$H18^(X$2+1))/(ε_c1cd^(X$2+1))) | Y18: =(INDIRECT("a_"&Y$2)/(Y$2+1))*(($C18^(Y$2+1)-$H18^(Y$2+1))/(ε_c1cd^(Y$2+1))) | Z18: =(INDIRECT("a_"&Z$2)/(Z$2+2))*(($C18^(Z$2+2)-$H18^(Z$2+2))/(ε_c1cd^(Z$2+2))) | AA18: =(INDIRECT("a_"&AA$2)/(AA$2+2))*(($C18^(AA$2+2)-$H18^(AA$2+2))/(ε_c1cd^(AA$2+2))) | AB18: =(INDIRECT("a_"&AB$2)/(AB$2+2))*(($C18^(AB$2+2)-$H18^(AB$2+2))/(ε_c1cd^(AB$2+2))) | AC18: =(INDIRECT("a_"&AC$2)/(AC$2+2))*(($C18^(AC$2+2)-$H18^(AC$2+2))/(ε_c1cd^(AC$2+2))) | AD18: =(INDIRECT("a_"&AD$2)/(AD$2+2))*(($C18^(AD$2+2)-$H18^(AD$2+2))/(ε_c1cd^(AD$2+2))) | AE18: =(b*f_cd/L18)*SUM(U18:Y18)+SUM(Q18:R18) | AF18: =AE18*(K18-y+e) | AG18: =(b*f_cd/(L18^2))*SUM(Z18:AD18)+SUM(S18:T18)-AF18 | AH18: =AG18<0 | AI18: =IF(A18=1,FALSE,(AND(AQ18,AH18,NOT(AI17)))) | AJ18: =(b*f_cd/L18)*(a_1/2*J18^2+a_2/3*J18^3+a_3/4*J18^4+a_4/5*J18^5+a_5/6*J18^6)+SUM(Q18:R18) | AK18: =AJ18*(K18-y+e) | AL18: =(b*f_cd/(L18^2))*(a_1/3*J18^3+a_2/4*J18^4+a_3/5*J18^5+a_4/6*J18^6+a_5/7*J18^7)+SUM(S18:T18)-AK18 | AM18: =AL18>0 | AN18: =IF(A18=1,FALSE,(AND(AQ18,AM18,NOT(AN17)))) | AO18: =IF(D18=1,AND(AH18,NOT(AI18)),AND(AM18,NOT(AN18))) | AP18: =IF(D18=1,AI18,AN18) | AQ18: =ABS(E18)<$AQ$2 | AS18: =IF(AP18,MAX(AS$3:AS16)+1,"")
A19: 17 | B19: =IF(A19=1,0,IF(AP19,0.1*ε_cu1cd,0)) | C19: =IF(A19=1,0.1*ε_cu1cd,C18+B18) | D19: =IF('Нормальний переріз'!$D$68>0,1,2) | E19: =IF(D19=1,F19,G19) | F19: =IF(AI18,0.11*ε_cu1cd,IF(AH18,F18*0.01,F18)) | G19: =IF(AP18,-0.1*ε_cu1cd,IF(AM18,G18*0.01,G18)) | H19: =IF(A19=1,E19,IF(AO18,H18-E18+E19,IF(AP18,0.8*H18,H18+E19))) | I19: =(C19-H19)/h | J19: =C19/(ε_c1cd) | K19: =C19/I19 | L19: =I19/(ε_c1cd) | M19: =I19*(K19-Z_s1) | N19: =I19*(K19-Z_s2) | O19: =E_s*M19 | P19: =E_s*N19 | Q19: =O19*A_s1 | R19: =P19*A_s2 | S19: =Q19*($K19-Z_s1) | T19: =R19*($K19-Z_s2) | U19: =(INDIRECT("a_"&U$2)/(U$2+1))*(($C19^(U$2+1)-$H19^(U$2+1))/(ε_c1cd^(U$2+1))) | V19: =(INDIRECT("a_"&V$2)/(V$2+1))*(($C19^(V$2+1)-$H19^(V$2+1))/(ε_c1cd^(V$2+1))) | W19: =(INDIRECT("a_"&W$2)/(W$2+1))*(($C19^(W$2+1)-$H19^(W$2+1))/(ε_c1cd^(W$2+1))) | X19: =(INDIRECT("a_"&X$2)/(X$2+1))*(($C19^(X$2+1)-$H19^(X$2+1))/(ε_c1cd^(X$2+1))) | Y19: =(INDIRECT("a_"&Y$2)/(Y$2+1))*(($C19^(Y$2+1)-$H19^(Y$2+1))/(ε_c1cd^(Y$2+1))) | Z19: =(INDIRECT("a_"&Z$2)/(Z$2+2))*(($C19^(Z$2+2)-$H19^(Z$2+2))/(ε_c1cd^(Z$2+2))) | AA19: =(INDIRECT("a_"&AA$2)/(AA$2+2))*(($C19^(AA$2+2)-$H19^(AA$2+2))/(ε_c1cd^(AA$2+2))) | AB19: =(INDIRECT("a_"&AB$2)/(AB$2+2))*(($C19^(AB$2+2)-$H19^(AB$2+2))/(ε_c1cd^(AB$2+2))) | AC19: =(INDIRECT("a_"&AC$2)/(AC$2+2))*(($C19^(AC$2+2)-$H19^(AC$2+2))/(ε_c1cd^(AC$2+2))) | AD19: =(INDIRECT("a_"&AD$2)/(AD$2+2))*(($C19^(AD$2+2)-$H19^(AD$2+2))/(ε_c1cd^(AD$2+2))) | AE19: =(b*f_cd/L19)*SUM(U19:Y19)+SUM(Q19:R19) | AF19: =AE19*(K19-y+e) | AG19: =(b*f_cd/(L19^2))*SUM(Z19:AD19)+SUM(S19:T19)-AF19 | AH19: =AG19<0 | AI19: =IF(A19=1,FALSE,(AND(AQ19,AH19,NOT(AI18)))) | AJ19: =(b*f_cd/L19)*(a_1/2*J19^2+a_2/3*J19^3+a_3/4*J19^4+a_4/5*J19^5+a_5/6*J19^6)+SUM(Q19:R19) | AK19: =AJ19*(K19-y+e) | AL19: =(b*f_cd/(L19^2))*(a_1/3*J19^3+a_2/4*J19^4+a_3/5*J19^5+a_4/6*J19^6+a_5/7*J19^7)+SUM(S19:T19)-AK19 | AM19: =AL19>0 | AN19: =IF(A19=1,FALSE,(AND(AQ19,AM19,NOT(AN18)))) | AO19: =IF(D19=1,AND(AH19,NOT(AI19)),AND(AM19,NOT(AN19))) | AP19: =IF(D19=1,AI19,AN19) | AQ19: =ABS(E19)<$AQ$2 | AS19: =IF(AP19,MAX(AS$3:AS17)+1,"")
... A2920: 2830 | B2920: =IF(A2920=1,0,IF(AP2920,0.1*ε_cu1cd,0)) | C2920: =IF(A2920=1,0.1*ε_cu1cd,C2919+B2919) | D2920: =IF('Нормальний переріз'!$D$68>0,1,2) | E2920: =IF(D2920=1,F2920,G2920) | F2920: =IF(AI2919,0.11*ε_cu1cd,IF(AH2919,F2919*0.01,F2919)) | G2920: =IF(AP2919,-0.1*ε_cu1cd,IF(AM2919,G2919*0.01,G2919)) | H2920: =IF(A2920=1,E2920,IF(AO2919,H2919-E2919+E2920,IF(AP2919,0.8*H2919,H2919+E2920))) | I2920: =(C2920-H2920)/h | J2920: =C2920/(ε_c1cd) | K2920: =C2920/I2920 | L2920: =I2920/(ε_c1cd) | M2920: =I2920*(K2920-Z_s1) | N2920: =I2920*(K2920-Z_s2) | O2920: =E_s*M2920 | P2920: =E_s*N2920 | Q2920: =O2920*A_s1 | R2920: =P2920*A_s2 | S2920: =Q2920*($K2920-Z_s1) | T2920: =R2920*($K2920-Z_s2) | U2920: =(INDIRECT("a_"&U$2)/(U$2+1))*(($C2920^(U$2+1)-$H2920^(U$2+1))/(ε_c1cd^(U$2+1))) | V2920: =(INDIRECT("a_"&V$2)/(V$2+1))*(($C2920^(V$2+1)-$H2920^(V$2+1))/(ε_c1cd^(V$2+1))) | W2920: =(INDIRECT("a_"&W$2)/(W$2+1))*(($C2920^(W$2+1)-$H2920^(W$2+1))/(ε_c1cd^(W$2+1))) | X2920: =(INDIRECT("a_"&X$2)/(X$2+1))*(($C2920^(X$2+1)-$H2920^(X$2+1))/(ε_c1cd^(X$2+1))) | Y2920: =(INDIRECT("a_"&Y$2)/(Y$2+1))*(($C2920^(Y$2+1)-$H2920^(Y$2+1))/(ε_c1cd^(Y$2+1))) | Z2920: =(INDIRECT("a_"&Z$2)/(Z$2+2))*(($C2920^(Z$2+2)-$H2920^(Z$2+2))/(ε_c1cd^(Z$2+2))) | AA2920: =(INDIRECT("a_"&AA$2)/(AA$2+2))*(($C2920^(AA$2+2)-$H2920^(AA$2+2))/(ε_c1cd^(AA$2+2))) | AB2920: =(INDIRECT("a_"&AB$2)/(AB$2+2))*(($C2920^(AB$2+2)-$H2920^(AB$2+2))/(ε_c1cd^(AB$2+2))) | AC2920: =(INDIRECT("a_"&AC$2)/(AC$2+2))*(($C2920^(AC$2+2)-$H2920^(AC$2+2))/(ε_c1cd^(AC$2+2))) | AD2920: =(INDIRECT("a_"&AD$2)/(AD$2+2))*(($C2920^(AD$2+2)-$H2920^(AD$2+2))/(ε_c1cd^(AD$2+2))) | AE2920: =(b*f_cd/L2920)*SUM(U2920:Y2920)+SUM(Q2920:R2920) | AF2920: =AE2920*(K2920-y+e) | AG2920: =(b*f_cd/(L2920^2))*SUM(Z2920:AD2920)+SUM(S2920:T2920)-AF2920 | AH2920: =AG2920<0 | AI2920: =IF(A2920=1,FALSE,(AND(AQ2920,AH2920,NOT(AI2919)))) | AJ2920: =(b*f_cd/L2920)*(a_1/2*J2920^2+a_2/3*J2920^3+a_3/4*J2920^4+a_4/5*J2920^5+a_5/6*J2920^6)+SUM(Q2920:R2920) | AK2920: =AJ2920*(K2920-y+e) | AL2920: =(b*f_cd/(L2920^2))*(a_1/3*J2920^3+a_2/4*J2920^4+a_3/5*J2920^5+a_4/6*J2920^6+a_5/7*J2920^7)+SUM(S2920:T2920)-AK2920 | AM2920: =AL2920>0 | AN2920: =IF(A2920=1,FALSE,(AND(AQ2920,AM2920,NOT(AN2919)))) | AO2920: =IF(D2920=1,AND(AH2920,NOT(AI2920)),AND(AM2920,NOT(AN2920))) | AP2920: =IF(D2920=1,AI2920,AN2920) | AQ2920: =ABS(E2920)<$AQ$2 | AS2920: =IF(AP2920,MAX(AS$3:AS2918)+1,"")

Sheet Вимірність
B1: Вимір | C1: Коефіцієнт для переведення в СІ
A2: Довжина | B2: мм | C2: 0.001
A3: =COUNTA(B2:B5) | B3: см | C3: 0.01
B4: м | C4: 1
A6: Сила | B6: кг | C6: =1/101936.799184506
A7: =COUNTA(B6:B11) | B7: т | C7: =1/101.936799184506
B8: H | C8: =1/1000000
B9: kH | C9: =1/1000
B10: MH | C10: 1
A12: Тиск | B12: МПа | C12: 1
A13: =COUNTA(B12:B16) | B13: т/м2 | C13: 101.9368
B14: т/см2 | C14: 0.01019368
B15: кг/см2 | C15: 10.19368
A17: Площа | B17: мм2 | C17: =1/1000000
A18: =COUNTA(B17:B20) | B18: см2 | C18: =1/10000
B19: м2 | C19: 1
A21: Кривизна | B21: 1/мм | C21: =1/1000
A22: =COUNTA(B21:B23) | B22: 1/см | C22: =1/100
B23: 1/м | C23: 1
A25: Момент | B25: т*м | C25: =1/101.936799184506
A26: =COUNTA(B25:B29) | B26: т*см | C26: =1/10193.6799184506
B27: кг*см | C27: =1/10193679.9184506
B28: МH*м | C28: 1
B29: кH*м | C29: =1/1000
B31: ‰ | C31: =1/1000

Sheet Налаштування
B2: Одиниці виміру для результатів: | F2: b= | G2: Довжина
B3: Розміри | C3: м | F3: h = | G3: Довжина
B4: Сили | C4: т | F4: A_s1= | G4: Площа
F5: A_s2= | G5: Площа
B6: Моменти | C6: =C4&C3 | F6: Z_s1= | G6: Довжина
B7: Тиск | C7: =C4&"/"&C3&"2" | F7: Z_s2= | G7: Довжина
B8: Площа | C8: =C3&"2" | F8: f_cd= | G8: Тиск
B9: Кривизна | C9: ="1/"&C3 | F9: ε_(cu1, cd)=
F10: ε_(c1, cd)=
F11: a_1=
F12: a_2=
F13: a_3=
F14: a_4=
F15: a_5=
F16: f_yk= | G16: Тиск
F17: E_s= | G17: Тиск
F18: f_ck= | G18: Тиск
F19: A_sl= | G19: Площа
F20: b_w= | G20: Довжина
F22: N_ed= | G22: Сила
F23: β=
F24: V_ed= | G24: Сила
F25: k=
F26: ρ_1=
F27: A_c= | G27: Площа
F28: σ_cp= | G28: Тиск
F29: C_Rdc=
F30: k_1=
F31: V_min= | G31: Сила
F32: V_Rdc= | G32: Сила
F33: ν=
F34: V_Rd= | G34: Сила
F35: γ_s =
F36: f_yd= | G36: Тиск
F37: ε_c1=
F38: ε_c2=
F39: χ= | G39: Кривизна
F40: γ=
F41: X_1= | G41: Довжина
F42: χ ̅=
...

Sheet Діарграма
A1: Номер точки | B1: ='Розвязок системи рівнянь'!D2 | C1: ='Розвязок системи рівнянь'!C2 | D1: ='Розвязок системи рівнянь'!H2 | E1: ='Розвязок системи рівнянь'!AF2 | F1: ='Розвязок системи рівнянь'!AK2
A2: 1 | B2: =INDEX('Розвязок системи рівнянь'!$A:$AS,MATCH($A2,RES_FindPointNum,0),MATCH(B$1,'Розвязок системи рівнянь'!$2:$2,0)) | C2: =INDEX('Розвязок системи рівнянь'!$A:$AS,MATCH($A2,RES_FindPointNum,0),MATCH(C$1,'Розвязок системи рівнянь'!$2:$2,0)) | D2: =INDEX('Розвязок системи рівнянь'!$A:$AS,MATCH($A2,RES_FindPointNum,0),MATCH(D$1,'Розвязок системи рівнянь'!$2:$2,0)) | E2: =INDEX('Розвязок системи рівнянь'!$A:$AS,MATCH($A2,RES_FindPointNum,0),MATCH(E$1,'Розвязок системи рівнянь'!$2:$2,0)) | F2: =INDEX('Розвязок системи рівнянь'!$A:$AS,MATCH($A2,RES_FindPointNum,0),MATCH(F$1,'Розвязок системи рівнянь'!$2:$2,0))
A3: 2 | B3: =INDEX('Розвязок системи рівнянь'!$A:$AS,MATCH($A3,RES_FindPointNum,0),MATCH(B$1,'Розвязок системи рівнянь'!$2:$2,0)) | C3: =INDEX('Розвязок системи рівнянь'!$A:$AS,MATCH($A3,RES_FindPointNum,0),MATCH(C$1,'Розвязок системи рівнянь'!$2:$2,0)) | D3: =INDEX('Розвязок системи рівнянь'!$A:$AS,MATCH($A3,RES_FindPointNum,0),MATCH(D$1,'Розвязок системи рівнянь'!$2:$2,0)) | E3: =INDEX('Розвязок системи рівнянь'!$A:$AS,MATCH($A3,RES_FindPointNum,0),MATCH(E$1,'Розвязок системи рівнянь'!$2:$2,0)) | F3: =INDEX('Розвязок системи рівнянь'!$A:$AS,MATCH($A3,RES_FindPointNum,0),MATCH(F$1,'Розвязок системи рівнянь'!$2:$2,0))
A4: 3 | B4: =INDEX('Розвязок системи рівнянь'!$A:$AS,MATCH($A4,RES_FindPointNum,0),MATCH(B$1,'Розвязок системи рівнянь'!$2:$2,0)) | C4: =INDEX('Розвязок системи рівнянь'!$A:$AS,MATCH($A4,RES_FindPointNum,0),MATCH(C$1,'Розвязок системи рівнянь'!$2:$2,0)) | D4: =INDEX('Розвязок системи рівнянь'!$A:$AS,MATCH($A4,RES_FindPointNum,0),MATCH(D$1,'Розвязок системи рівнянь'!$2:$2,0)) | E4: =INDEX('Розвязок системи рівнянь'!$A:$AS,MATCH($A4,RES_FindPointNum,0),MATCH(E$1,'Розвязок системи рівнянь'!$2:$2,0)) | F4: =INDEX('Розвязок системи рівнянь'!$A:$AS,MATCH($A4,RES_FindPointNum,0),MATCH(F$1,'Розвязок системи рівнянь'!$2:$2,0))
A5: 4 | B5: =INDEX('Розвязок системи рівнянь'!$A:$AS,MATCH($A5,RES_FindPointNum,0),MATCH(B$1,'Розвязок системи рівнянь'!$2:$2,0)) | C5: =INDEX('Розвязок системи рівнянь'!$A:$AS,MATCH($A5,RES_FindPointNum,0),MATCH(C$1,'Розвязок системи рівнянь'!$2:$2,0)) | D5: =INDEX('Розвязок системи рівнянь'!$A:$AS,MATCH($A5,RES_FindPointNum,0),MATCH(D$1,'Розвязок системи рівнянь'!$2:$2,0)) | E5: =INDEX('Розвязок системи рівнянь'!$A:$AS,MATCH($A5,RES_FindPointNum,0),MATCH(E$1,'Розвязок системи рівнянь'!$2:$2,0)) | F5: =INDEX('Розвязок системи рівнянь'!$A:$AS,MATCH($A5,RES_FindPointNum,0),MATCH(F$1,'Розвязок системи рівнянь'!$2:$2,0))
A6: 5 | B6: =INDEX('Розвязок системи рівнянь'!$A:$AS,MATCH($A6,RES_FindPointNum,0),MATCH(B$1,'Розвязок системи рівнянь'!$2:$2,0)) | C6: =INDEX('Розвязок системи рівнянь'!$A:$AS,MATCH($A6,RES_FindPointNum,0),MATCH(C$1,'Розвязок системи рівнянь'!$2:$2,0)) | D6: =INDEX('Розвязок системи рівнянь'!$A:$AS,MATCH($A6,RES_FindPointNum,0),MATCH(D$1,'Розвязок системи рівнянь'!$2:$2,0)) | E6: =INDEX('Розвязок системи рівнянь'!$A:$AS,MATCH($A6,RES_FindPointNum,0),MATCH(E$1,'Розвязок системи рівнянь'!$2:$2,0)) | F6: =INDEX('Розвязок системи рівнянь'!$A:$AS,MATCH($A6,RES_FindPointNum,0),MATCH(F$1,'Розвязок системи рівнянь'!$2:$2,0))
